Workbook

Sheet Lo trinh cong danh
A1: LỘ TRÌNH CÔNG DANH - ADE 2025 -BP TỰ ĐỘNG HÓA RV03
A2: Stt | B2: Kỹ năng/ Kiến thức/ Thái độ/ Kết quả/ Thời gian cống hiến | C2: Staff | D2: Senior | E2: Leader | F2: Manager | G2: Lộ trình | H2: Lộ trình | I2: CEO | J2: Tài liệu Training (Link) | K2: Biểu mẫu áp dụng | L2: Người đào tạo | M2: Lê Công Dũng Manager | N2: Hồ Hữu Thanh Sơn Leader | O2: Tăng Phú Vinh Staff
A4: A | B4: KỸ NĂNG
A5: I | B5: Group 1. Kỹ năng cơ bản | G5: < 2 tháng (kể từ khi nhận việc) | L5: TBP
A6: 1 | B6: Kỹ năng lập kế hoạch hàng ngày (Kế hoạch 5 phút) | C6: x | D6: x | E6: x | F6: x | H6: Passed | J6: To do List (Excell) | N6: x
A7: 2 | B7: Kỹ năng lập kế hoạch, báo cáo tuần/ tháng/ quí/ năm | C7: x | D7: x | E7: x | F7: x | H7: Passed | J7: Project Follow | N7: x
A8: 3 | B8: Kỹ năng làm việc theo qui trình, không có qui trình thì thực hiện theo hướng dẫn của người quản lý trực tiếp | C8: x | D8: x | E8: x | F8: x | H8: Passed | J8: Qui trình | N8: x
A9: 4 | B9: Kỹ năng sử dụng phần mềm vào công việc được giao | C9: x | D9: x | E9: x | F9: x | H9: Passed | J9: Microsoft office, phần mềm báo cáo, AutoCAD) | L9: Tự học/ Trưởng nhóm | N9: x
A10: 5 | B10: Kỹ năng Làm việc nhóm hoặc độc lập | C10: x | D10: x | E10: x | F10: x | H10: Passed | J10: A Tân cung cấp | L10: TBP | N10: x
A11: 6 | B11: Kỹ năng nhận dạng và giải quyết vấn đề | C11: x | D11: x | E11: x | F11: x | H11: Passed | J11: A Tân cung cấp | L11: TBP | N11: x
A12: 7 | B12: Tiếng anh/ đọc hiểu bản vẽ, tài liệu tiếng anh | C12: x | D12: x | E12: x | F12: x | H12: Passed | J12: A Tân cung cấp | L12: Tự hoc | N12: x
A13: 8 | B13: Quản lý thời gian | C13: x | D13: x | E13: x | F13: x | H13: Passed | J13: A Tân cung cấp | L13: TBP | N13: x
A14: 9 | B14: Đọc hiểu bản vẽ | C14: x | D14: x | E14: x | F14: x | H14: Passed | J14: Bản vẽ dự án thực tế | L14: TBP | N14: x
A15: II | B15: Group 2. Kỹ năng nâng cao
A16: 1 | B16: Kỹ năng phân tích rủi ro thi công | D16: x | E16: x | F16: x | G16: < 3 tháng | H16: Passed | J16: Qui trình đã ban hành | L16: A Trọng/ TBP | N16: x
A17: 2 | B17: Kỹ năng xây dựng qui trình | E17: x | F17: x | G17: < 4 tháng | H17: Passed | J17: A Hưng cung cấp | L17: A Trọng/ TBP | N17: x
A18: 3 | B18: Xây dựng KPI, chính sách phúc lợi cho phòng | F18: x | G18: < 5 tháng | H18: Passed | J18: HS, xây dựng LTCD và lương 3P | L18: TBP
A19: 4 | B19: Quản lý đội nhóm & tạo động lực cho nhân viên | E19: x | F19: x | G19: < 6 tháng | H19: Passed | J19: A Tân cung cấp | L19: TBP | N19: x
A20: 5 | B20: Kỹ năng Đào tạo nhân viên | E20: x | F20: x | G20: < 7 tháng | H20: Passed | J20: Qui trình đào tạo (theo Lộ trình đào tạo) | L20: TBP | N20: x
A21: 6 | B21: Kỹ năng Điều phối cuộc họp | E21: x | F21: x | G21: < 8 tháng | H21: Passed | J21: A Hưng cung cấp | L21: TBP
A22: 7 | B22: Kỹ năng giám sát đội nhóm | E22: x | F22: x | G22: < 9 tháng | H22: Passed | J22: A Hưng cung cấp | L22: TBP | N22: x
A23: 8 | B23: Tiếng anh/ đọc hiểu và trả lời mail, tài liệu, giao tiếp được | D23: x | E23: x | F23: x | G23: < 12 tháng | H23: Passed | J23: A Tân cung cấp | L23: TBP
A24: III | B24: Group 3. Kỹ năng chuyên nghiệp
A25: 1 | B25: Kỹ năng giao tiếp & xây dựng mối quan hệ | D25: x | E25: x | F25: x | H25: < 1 tháng | J25: A Tân cung cấp | L25: TBP | N25: x
A26: 2 | B26: Quản lý thời gian | E26: x | F26: x | H26: < 1 tháng | J26: A Tân cung cấp | L26: TBP | N26: x
A27: 3 | B27: Tiếng anh/ đọc hiểu và trả lời mail, tài liệu, giao tiếp được vs người nước ngoài | E27: x | F27: x | H27: < 6 tháng | J27: A Tân cung cấp | L27: TBP
A28: 4 | B28: Quản trị hệ thống & qui trình | E28: x | F28: x | H28: < 2 tháng | J28: A Trọng cung cấp Index QT ISO (Update) | L28: TBP
A29: 5 | B29: Giám sát và điều hành | E29: x | F29: x | H29: < 2 tháng | J29: A Tân cung cấp | L29: TBP | N29: x
A30: 6 | B30: Kỹ năng giao việc và huấn luyện | E30: x | F30: x | H30: < 2 tháng | J30: A Tân cung cấp | L30: TBP | N30: x
A31: 7 | B31: Lập kế hoạch, xây dựng chiến lược triển khai quản lý dự án | E31: x | F31: x | H31: < 3 tháng | J31: A Tân cung cấp | L31: TBP
A32: 8 | B32: Quản trị rủi ro | D32: x | E32: x | F32: x | H32: < 3 tháng | J32: A Trọng cung cấp Index QT ISO (Update) | L32: TBP | N32: x
A33: 9 | B33: Hoạch định chiến lược | F33: x | H33: < 3 tháng | J33: A Tân cung cấp | L33: TBP
A34: 10 | B34: Phân tích và ra quyết định | F34: x | H34: < 4 tháng | J34: A Tân cung cấp | L34: TBP | N34: x
A35: 11 | B35: Quản trị sự thay đổi | F35: x | H35: < 4 tháng | J35: A Tân cung cấp | L35: TBP
A36: 12 | B36: Quản trị hệ thống | F36: x | H36: < 6 tháng | J36: A Trọng cung cấp Index QT ISO (Update) | L36: TBP
A37: B | B37: KIẾN THỨC
A38: I | B38: Kiến thức nền (Các công thức, phương pháp)
A39: 1 | B39: Công thức tính công suất hiệu dụng (P) | C39: x | D39: x | E39: x | F39: x | G39: < 2 Tuần | H39: Passed | J39: A Tân cung cấp | L39: A Trọng/ TBP | N39: x
A40: 2 | B40: Công thức tính công suất biểu kiến (S) | C40: x | D40: x | E40: x | F40: x | G40: < 2 Tuần | H40: Passed | J40: A Tân cung cấp | L40: A Trọng/ TBP | N40: x
A41: 3 | B41: Công thức tính dòng điện hiệu dụng (A) | C41: x | D41: x | E41: x | F41: x | G41: < 2 Tuần | H41: Passed | J41: A Tân cung cấp | L41: A Trọng/ TBP | N41: x
...

Sheet P2.1(Kiến Thức)
A1: CÔNG TY TNHH KỸ THUẬT TỰ ĐỘNG AN DƯƠNG
A2: ĐÁNH GIÁ NHÂN VIÊN KỸ THUẬT LẬP TRÌNH
B3: Ngày: 30/04/2026 | E3: Người đánh giá | F3: Lê Công Dũng
B4: Mục đích kiểm tra/ đánh giá: Đánh giá lương tháng 4
A5: ĐIỂM CHUẨN CẦN PHẢI ĐÁP ỨNG HƯỞNG LƯƠNG THEO VỊ TRÍ - P2.1 (theo kiến thức công việc)
A6: Stt | B6: Kỹ năng/ Kiến thức/ Thái độ/ Kết quả/ Thời gian làm việc | C6: Thang điểm Cộng/ trừ (Tham khảo) | D6: Thang điểm 100 | E6: Diễn giải | F6: Hồ Hữu Thanh Sơn | G6: Tăng Phú Vinh
A7: A (TC1) | B7: KỸ NĂNG | D7: =D8+D18+D27 -> 35 | E7: KỸ NĂNG | F7: =F8+F18+F27 -> 34 | G7: =G8+G18+G27 -> 14
A8: I | B8: Group 1. Kỹ năng cơ bản | D8: 15 | E8: Group 1. Kỹ năng cơ bản | F8: =$D$8+SUM(F9:F17) -> 15 | G8: =$D$8+SUM(G9:G17) -> 10
A9: 1 | B9: Không có kế hoạch hàng ngày (Kế hoạch 5 phút) | C9: -1 | E9: Kỹ năng lập kế hoạch hàng ngày (Kế hoạch 5 phút)
A10: 2 | B10: Không có kế hoạch, báo cáo tuần/ tháng/ quí/ năm | C10: -2 | E10: Kỹ năng lập kế hoạch, báo cáo tuần/ tháng/ quí/ năm
A11: 3 | B11: Không làm việc theo qui trình, không thực hiện theo hướng dẫn của người quản lý trực tiếp | C11: -2 | E11: Kỹ năng làm việc theo qui trình, không có qui trình thì thực hiện theo hướng dẫn của người quản lý trực tiếp
A12: 4 | B12: Không sử dụng phần mềm vào công việc được giao | C12: -1 | E12: Kỹ năng sử dụng phần mềm vào công việc được giao
A13: 5 | B13: Không hợp tác Làm việc nhóm | C13: -2 | E13: Kỹ năng Làm việc nhóm hoặc độc lập | G13: -1
A14: 6 | B14: Không chủ động nhận dạng và giải quyết vấn đề | C14: -2 | E14: Kỹ năng nhận dạng và giải quyết vấn đề | G14: -1
A15: 7 | B15: Sai chính tả Tiếng anh | C15: -1 | E15: Tiếng anh/ đọc hiểu bản vẽ, tài liệu tiếng anh | G15: -1
A16: 8 | B16: Không biết Quản lý thời gian & sắp xếp công việc phù hợp | C16: -2 | E16: Quản lý thời gian | G16: -2
A17: 9 | B17: Không hiểu bản vẽ, không kiểm tra bản vẽ trước khi gởi đi | C17: -2 | E17: Đọc hiểu bản vẽ
A18: II | B18: Group 2. Kỹ năng nâng cao | D18: 10 | E18: Group 2. Kỹ năng nâng cao | F18: =$D$18+SUM(F19:F26) -> 10 | G18: =$D$18+SUM(G19:G26) -> 3
A19: 1 | B19: Không thực hiện phân tích rủi ro thi công | C19: -1 | E19: Kỹ năng phân tích rủi ro thi công
A20: 2 | B20: Không biết viết qui trình/ hướng dẫn/ bảng cài đặt... | C20: -2 | E20: Kỹ năng xây dựng qui trình | G20: -2
A21: 3 | B21: Xây dựng KPI, chính sách phúc lợi cho phòng | C21: +1 | E21: Xây dựng KPI, chính sách phúc lợi cho phòng | G21: -1
A22: 4 | B22: Quản lý đội nhóm & tạo động lực cho nhân viên | C22: +1 | E22: Quản lý đội nhóm & tạo động lực cho nhân viên | G22: -1
A23: 5 | B23: Kỹ năng Đào tạo nhân viên | C23: +1 | E23: Kỹ năng Đào tạo nhân viên | G23: -1
A24: 6 | B24: Kỹ năng Điều phối cuộc họp | C24: +1 | E24: Kỹ năng Điều phối cuộc họp | G24: -1
A25: 7 | B25: Kỹ năng giám sát đội nhóm | C25: +1 | E25: Kỹ năng giám sát đội nhóm
A26: 8 | B26: Tiếng anh/ đọc hiểu và trả lời mail, tài liệu, giao tiếp được | C26: +1 | E26: Tiếng anh/ đọc hiểu và trả lời mail, tài liệu, giao tiếp được | G26: -1
A27: III | B27: Group 3. Kỹ năng chuyên nghiệp | D27: 10 | E27: Group 3. Kỹ năng chuyên nghiệp | F27: =$D$27+SUM(F28:F40) -> 9 | G27: =$D$27+SUM(G28:G40) -> 1
A28: 7 | B28: Kỹ năng giao tiếp & xây dựng mối quan hệ | C28: -1 | E28: Kỹ năng giao tiếp & xây dựng mối quan hệ
A29: 5 | B29: Quản lý thời gian | C29: -2 | E29: Quản lý thời gian | G29: -2
A30: 1 | B30: Tiếng anh/ đọc hiểu và trả lời mail, tài liệu, giao tiếp được vs người nước ngoài | C30: -1 | E30: Tiếng anh/ đọc hiểu và trả lời mail, tài liệu, giao tiếp được vs người nước ngoài | F30: -1 | G30: -1
A31: 2 | B31: Quản trị hệ thống & qui trình | C31: -1 | E31: Quản trị hệ thống & qui trình | G31: -1
A32: 3 | B32: Giám sát và điều hành | C32: -1 | E32: Giám sát và điều hành | G32: -1
A33: 4 | B33: Kỹ năng giao việc và huấn luyện | C33: -1 | E33: Kỹ năng giao việc và huấn luyện | G33: -1
A34: 6 | B34: Lập kế hoạch, xây dựng chiến lược triển khai quản lý dự án | C34: -1 | E34: Lập kế hoạch, xây dựng chiến lược triển khai quản lý dự án | G34: -1
A35: 8 | B35: Quản trị rủi ro | C35: -2 | E35: Quản trị rủi ro | G35: -2
A36: 9 | B36: Hoạch định chiến lược | C36: +1 | E36: Hoạch định chiến lược | G36: 0
A37: 10 | B37: Phân tích và ra quyết định | C37: +1 | E37: Phân tích và ra quyết định | G37: 0
A38: 11 | B38: Quản trị sự thay đổi | C38: +1 | E38: Quản trị sự thay đổi | G38: 0
A39: 12 | B39: Quản trị hệ thống | C39: +1 | E39: Quản trị hệ thống | G39: 0
A41: B (TC2) | B41: KIẾN THỨC | D41: =D42+D62+D105+D118 -> 40 | E41: KIẾN THỨC | F41: =F42+F62+F105+F118 -> 32 | G41: =G42+G62+G105+G118 -> 14
...

Sheet P2.2 (Kỹ Năng chuyên Môn)
D2: BẢNG TỔNG HỢP ĐÁNH GIÁ THỰC HIỆN CÔNG VIỆC CÔNG NHÂN VIÊN | T2: Mã số
T3: Lần ban hành
T4: Lần sửa đổi
H6: PHÒNG: Tự Động Hóa
H7: Tháng: 04/2026
B9: STT | C9: HỌ VÀ TÊN | D9: CHỨC VỤ | E9: CHỈ TIÊU ĐÁNH GIÁ | U9: TỔNG ĐIỂM | V9: XẾP LOẠI | W9: GHI CHÚ
E10: 1 | F10: 2 | G10: 3 | H10: 4 | I10: 5 | J10: 6 | K10: 7 | L10: 8 | M10: 9 | N10: 10 | O10: 11 | P10: 12 | Q10: 13 | R10: 14 | S10: 15 | T10: 16
E11: Tay nghề & Kỹ năng thực hiện công việc | F11: Chất lượng thực hiện công việc (tuân thủ các mục tiêu chuẩn & quy trình) | G11: Khối lượng & tiến độ công việc hoàn thành | H11: Làm việc nhóm & Hợp tác thực hiện công việc | I11: Ý thức đảm bảo an toàn lao động | J11: Ý thức bảo vệ tài sản của công ty & CĐT tại công trường | K11: Ý thức sử dụng tiết kiệm tài sản của Công ty (điện, nước, vật tư, thiết bị lắp đặt…) | L11: Thái độ, ý thức trách nhiệm đối với công việc | M11: Quan hệ với đồng nghiệp & những người khác trên công trường | N11: Kỷ luật trong CV, ý thức chấp hành nội quy công ty | O11: Mặc đồng phục, đeo thẻ đầy đủ & đúng quy định | P11: Ý thức sử dụng thời gian làm việc | Q11: Ý thức chấp hành lệnh phân công, điều hành của quản trị viên, BGĐ | R11: Giữ gìn vệ sinh | S11: Đi làm đầy đủ | T11: Đi làm đúng giờ
E12: 8 | F12: 8 | G12: 8 | H12: 8 | I12: 8 | J12: 6 | K12: 6 | L12: 6 | M12: 6 | N12: 6 | O12: 6 | P12: 6 | Q12: 6 | R12: 4 | S12: 4 | T12: 4 | U12: =SUM(E12:T12) -> 100
B13: 1 | C13: Hồ Hữu Thanh Sơn | D13: CN | E13: ='[1]Hồ Hữu Thanh Sơn'!J12 -> 7 | F13: ='[1]Hồ Hữu Thanh Sơn'!J17 -> 6 | G13: ='[1]Hồ Hữu Thanh Sơn'!J19 -> 6 | H13: ='[1]Hồ Hữu Thanh Sơn'!J21 -> 8 | I13: ='[1]Hồ Hữu Thanh Sơn'!J23 -> 8 | J13: ='[1]Hồ Hữu Thanh Sơn'!J25 -> 6 | K13: ='[1]Hồ Hữu Thanh Sơn'!J27 -> 6 | L13: ='[1]Hồ Hữu Thanh Sơn'!J29 -> 6 | M13: ='[1]Hồ Hữu Thanh Sơn'!J31 -> 6 | N13: ='[1]Hồ Hữu Thanh Sơn'!J33 -> 6 | O13: ='[1]Hồ Hữu Thanh Sơn'!J35 -> 6 | P13: ='[1]Hồ Hữu Thanh Sơn'!J37 -> 6 | Q13: ='[1]Hồ Hữu Thanh Sơn'!J39 -> 6 | R13: ='[1]Hồ Hữu Thanh Sơn'!J41 -> 4 | S13: ='[1]Hồ Hữu Thanh Sơn'!J43 -> 2 | T13: ='[1]Hồ Hữu Thanh Sơn'!J45 -> 4 | U13: =SUM(E13:T13) -> 93
D14: Chỉ huy công trình đánh giá
C15: Lê Công Dũng | D15: QTV đánh giá | E15: ='[1]Hồ Hữu Thanh Sơn'!L12 -> 7 | F15: ='[1]Hồ Hữu Thanh Sơn'!L17 -> 6 | G15: ='[1]Hồ Hữu Thanh Sơn'!L19 -> 6 | H15: ='[1]Hồ Hữu Thanh Sơn'!L23 -> 8 | I15: ='[1]Hồ Hữu Thanh Sơn'!L23 -> 8 | J15: ='[1]Hồ Hữu Thanh Sơn'!L25 -> 6 | K15: ='[1]Hồ Hữu Thanh Sơn'!L29 -> 6 | L15: ='[1]Hồ Hữu Thanh Sơn'!L31 -> 6 | M15: ='[1]Hồ Hữu Thanh Sơn'!L31 -> 6 | N15: ='[1]Hồ Hữu Thanh Sơn'!L33 -> 6 | O15: ='[1]Hồ Hữu Thanh Sơn'!L35 -> 6 | P15: ='[1]Hồ Hữu Thanh Sơn'!L37 -> 6 | Q15: ='[1]Hồ Hữu Thanh Sơn'!L39 -> 6 | R15: ='[1]Hồ Hữu Thanh Sơn'!L41 -> 4 | S15: ='[1]Hồ Hữu Thanh Sơn'!L43 -> 2 | T15: ='[1]Hồ Hữu Thanh Sơn'!L45 -> 4 | U15: =SUM(E15:T15) -> 93
B16: 2 | C16: Tăng Phú Vinh | D16: CN | E16: ='[1]Tăng Phú Vinh'!J12 -> 5 | F16: ='[1]Tăng Phú Vinh'!J17 -> 5 | G16: ='[1]Tăng Phú Vinh'!J19 -> 6 | H16: ='[1]Tăng Phú Vinh'!J21 -> 7 | I16: ='[1]Tăng Phú Vinh'!J23 -> 7 | J16: ='[1]Tăng Phú Vinh'!J25 -> 6 | K16: ='[1]Tăng Phú Vinh'!J27 -> 6 | L16: ='[1]Tăng Phú Vinh'!J29 -> 6 | M16: ='[1]Tăng Phú Vinh'!J31 -> 6 | N16: ='[1]Tăng Phú Vinh'!J33 -> 6 | O16: ='[1]Tăng Phú Vinh'!J35 -> 6 | P16: ='[1]Tăng Phú Vinh'!J37 -> 5 | Q16: ='[1]Tăng Phú Vinh'!J39 -> 6 | R16: ='[1]Tăng Phú Vinh'!J41 -> 6 | S16: ='[1]Tăng Phú Vinh'!J43 -> 0 | T16: ='[1]Tăng Phú Vinh'!J45 -> 4 | U16: =SUM(E16:T16) -> 87
D17: Chỉ huy công trình đánh giá
C18: Lê Công Dũng | D18: QTV đánh giá | E18: ='[1]Tăng Phú Vinh'!L12 -> 5 | F18: ='[1]Tăng Phú Vinh'!L17 -> 5 | G18: ='[1]Tăng Phú Vinh'!L19 -> 6 | H18: ='[1]Tăng Phú Vinh'!L21 -> 7 | I18: ='[1]Tăng Phú Vinh'!L23 -> 7 | J18: ='[1]Tăng Phú Vinh'!L25 -> 6 | K18: ='[1]Tăng Phú Vinh'!L27 -> 6 | L18: ='[1]Tăng Phú Vinh'!L29 -> 6 | M18: ='[1]Tăng Phú Vinh'!L31 -> 6 | N18: ='[1]Tăng Phú Vinh'!L33 -> 6 | O18: ='[1]Tăng Phú Vinh'!L35 -> 6 | P18: ='[1]Tăng Phú Vinh'!L37 -> 5 | Q18: ='[1]Tăng Phú Vinh'!L39 -> 6 | R18: ='[1]Tăng Phú Vinh'!L41 -> 6 | S18: ='[1]Tăng Phú Vinh'!L43 -> 0 | T18: ='[1]Tăng Phú Vinh'!L45 -> 4 | U18: =SUM(E18:T18) -> 87
P20: Ngày 30 tháng 04 năm 2026
D21: Trưởng Phòng | P21: Giám đốc chuyên trách
D22: (Hoặc Trưởng Bộ phận
D23: Bảo trì, Phó trưởng VPĐD)
D27: Lê Công Dũng

Sheet P3.1.2 (Staff)
C1: QUẢN TRỊ HIỆU SUẤT | D1: CÔNG TY TNHH KỸ THUẬT TỰ ĐỘNG AN DƯƠNG BẢNG KPI NHÂN VIÊN THÁNG 6 NĂM 2024
C3: Căn cứ quy định đánh giá hiệu quả công việc hiện hành
C4: Căn cứ kế hoạch phát triển công ty
A6: Phòng Tự Động | B6: Mục tiêu chiến lược | C6: Yếu tố quyết định thành công | D6: Chỉ tiêu đánh giá (KPI) | E6: Stt KPI | F6: Đơn vị đo lường | G6: Trọng số (%) | I6: Mục tiêu 2024 | J6: Kém | K6: Xuất sắc | L6: Điểm Đánh Giá KPI Cá Nhân
L7: Họ và tên NV
H8: Thực hiện cùng kỳ 2023 | L8: Số lần vi phạm | M8: Điểm thưởng bị trừ
A9: TỔNG CỘNG | G9: =SUM(G10:G26) -> 1 | L9: =SUM(L10:L26) -> 0 | M9: =SUM(M10:M26) -> 0
A10: An Toàn | B10: Trang thiết bị bảo hộ lao động | C10: Thiết bị thi công, công cụ, dụng cụ đảm bảo tiêu chuẩn an toàn | D10: Các thiết bị thi công phải đúng kỹ thuật, không sử dụng thiết bị hư hỏng làm ảnh hưởng đến chất lượng và thẩm mỹ. | E10: P.AU-KPI 1 | F10: Số lần vi phạm / tháng (kiểm tra 2 lần/ ngày) | G10: 0.15 | I10: 0 Lần / Tháng | J10: 1 Lần/Tháng | K10: 0 Lần / Tháng | L10: 0 | M10: =IF(SUM(L10:L12)>=1,$G$10,0) -> 0
C11: Được trang bị đầy đủ đồ bảo hộ lao động | D11: Trang bị đầy đủ đồ bảo hộ lao động khi làm việc tại công trường theo quy định | F11: Số lần không trang bị đầy đủ đồ bảo hộ lao động | I11: 0 Lần / Tháng | J11: 1 Lần/Tháng | K11: 0 Lần / Tháng
B12: Đảm bảo an toàn trong công việc | C12: Không xảy ra nguy cơ tai nạn lao động tại công trình | D12: Không xảy ra tai nạn lao động tại nơi làm việc, công trường | F12: Số lần tai nạn trong tháng | I12: 0 Lần / Tháng | J12: 1 Lần/Tháng | K12: 0 Lần / Tháng | L12: 0
C13: Tuyệt đối không hút thuốc trong công trình | D13: Cấm tuyệt đối hút thuốc tại công trường | F13: Số lần hút thuốc tại cộng trình | I13: 0 Lần / Tháng | J13: 1 Lần/Tháng | K13: 0 Lần / Tháng
A14: Kỹ thuật/ Chất lượng | B14: Lập trình hệ thống đúng yêu cầu của khách hàng | C14: Sự hài lòng của khách hàng Sản phẩm đạt chất lượng kỹ thuật | D14: Thực hiện công việc lập trình không đúng Control Panel hoặc lập bảng Control Panel không đúng yêu cầu của khách hàng dẫn đến phải sửa đổi chương trình/ cài đặt nhiều hơn 1 lần. | E14: P.AU-KPI 2 | F14: Số lần phát sinh thay đổi viết lại chương trình cho một công đoạn nhiều hơn 1 lần trong 01 tháng. | G14: 0.2 | I14: 0 Lỗi / DA/ Việc | J14: 1 Lỗi / DA/việc | K14: 0 Lỗi / DA/việc | L14: 0 | M14: =IF(SUM(L14:L15)>=1,$G$14,0) -> 0
B15: Thi công lắp đặt, cài đặt/ sửa chữa đạt tiêu chuẩn kỹ thuật, chất lượng | C15: Chất lượng lắp đặt, cài đặt, hiệu chỉnh | D15: Thi công, lắp đặt cài đặt sửa chữa đúng nguyên lý, đúng kỹ thuật, đúng bản vẽ, đảm bảo về thẩm mỹ kỹ thuật | F15: Số lỗi thi công, cài đặt sữa chữa không đúng thiết kế gây ra hư hỏng, hoặc khách hàng phản ánh trong 01 tháng | I15: 0 Lỗi / DA/ Việc | J15: 1 Lỗi / DA/việc | K15: 0 Lỗi / DA/việc | L15: 0
A16: Qui trình | B16: Quy trình và quản lý chất lượng | C16: Quy trình và quản lý An toàn, chất lượng, Kỹ thuật | D16: Thực hiện công việc theo đúng quy trình | E16: P.AU-KPI 3 | F16: Số lần không áp dụng qui trình/ tháng | G16: 0.15 | I16: 0 | J16: 1 | K16: 0 | L16: 0 | M16: =IF(SUM(L16:L18)>=1,$G$16,0) -> 0
C17: Hiệu suất | D17: 100% hoàn thành công việc theo quy trình | F17: Tỷ lệ % hoàn thành công việc theo quy trình | I17: 1 | J17: <100% | K17: 1 | L17: 0
D18: Thực hiện qui trình 5S tại nơi làm việc | F18: Số lần vi phạm/ ko thực hiện/tháng | I18: 0 | J18: 1 Lần | K18: 0 | L18: 0
A19: Tiến độ | B19: Tiến độ hoàn thành công việc | C19: Tiến độ thực hiện công việc đúng tiến độ chung của dự án | D19: Thực hiện công việc nhanh chóng không ì ạch, không tập trung, chậm trễ tiến độ chung với dự án | E19: P.AU-KPI 4 | F19: Số lần trễ tiến độ /dự\ án | G19: 0.15 | I19: 0 Lần | J19: 1 | K19: 0 Lần | L19: 0 | M19: =IF(SUM(L19:L20)>=1,$G$19,0) -> 0
D20: Đảm bảo báo cáo công việc hàng ngày và hàng tuần | F20: Số lần báo cáo không kịp thời, không đạt yêu cầu/tháng | I20: 0 Lần | J20: 1 | K20: 0 Lần | L20: 0
A21: Chi Phí | B21: Giới hạn chi phí phát sinh thay đổi | C21: Giảm thiểu chi phí | D21: Làm mất mát, thất thoát vật tư tại nơi làm việc | E21: P.AU-KPI 5 | F21: Số lần làm mất mát thất thoát vật tư | G21: 0.15 | I21: 0 Lần | J21: 1 Lần | K21: 0 Lần | L21: 0 | M21: =IF(SUM(L21:L22)>=1,$G$21,0) -> 0
D22: Cắt dây điện đúng kích thước, sai số cho phép theo quy định | F22: Sai lệch so với thực tế thi công +/- 2% | I22: 0.01 | J22: <2%, >2% | K22: </= 1% | L22: 0
A23: Đào tạo và Phẫm chất | B23: Đào tạo nhân sự | C23: Tham gia 100% các buổi training do phòng ban tổ chức | D23: Tham dự đào tạo và nhận kết quả đào tạo theo kế hoạch đào tạo của phòng ban | E23: P.AU-KPI 6 | F23: % số khóa đào tạo thực hiện/kế hoạch | G23: 0.15 | I23: >80% | J23: <80% | K23: 100% | L23: 0 | M23: =IF(SUM(L23:L25)>=1,$G$23,0) -> 0
D24: Tham gia training From fails ít nhất 01 lần/ tháng | F24: % nhân sự đạt yêu cầu /tổng số nhân viên phòng ban | I24: >80% | J24: <80% | K24: 100% | L24: 0
B25: Tuân thủ nội quy quy chế công ty | C25: Nội quy công ty, nội quy công trình | D25: Tuân thủ nội quy công ty, nội quy công trình | F25: Số lần vi phạm /tháng | I25: 0 lần / tháng | J25: 2lần / tháng | K25: 0 lần / tháng | L25: 0
A26: Thẩm Mỹ | B26: Sản phẩm, Dịch vụ | C26: Tiêu chí đạt thẩm mỹ | D26: Không có phàn nàn từ khách hàng hoặc các cấp quản lý về chất lượng thẩm mỹ của dự án đang thực hiện | E26: P.AU-KPI 7 | F26: Số lần phàn nàn về chất lượng, thẩm mỹ | G26: 0.05 | I26: 0 | J26: 1 | K26: 0 | L26: 0 | M26: =IF(SUM(L26:L26)>=1,$G$26,0) -> 0

Sheet P3.1.1 (KPI Senior)
C1: QUẢN TRỊ HIỆU SUẤT | D1: CÔNG TY TNHH KỸ THUẬT TỰ ĐỘNG AN DƯƠNG BẢNG KPI NHÂN VIÊN THÁNG 04 NĂM 2026
C3: Căn cứ quy định đánh giá hiệu quả công việc hiện hành
C4: Căn cứ kế hoạch phát triển công ty
A6: Phòng Tự Động | B6: Mục tiêu chiến lược | C6: Yếu tố quyết định thành công | D6: Chỉ tiêu đánh giá (KPI) | E6: Stt KPI | F6: Đơn vị đo lường | G6: Trọng số (%) | I6: Mục tiêu 2025 | J6: Kém | K6: Xuất sắc | L6: Điểm Đánh Giá | N6: Điểm Đánh Giá
L7: Hồ Hữu Thanh Sơn | N7: Tăng Phú Vinh
H8: Thực hiện cùng kỳ 2023 | L8: Số lần vi phạm | M8: Điểm thưởng bị trừ | N8: Số lần vi phạm | O8: Điểm thưởng bị trừ
A9: TỔNG CỘNG | G9: =SUM(G10:G32) -> 1 | L9: =SUM(L12:L32) -> 0 | M9: =SUM(M10:M32) -> 0 | N9: =SUM(N12:N32) -> 0 | O9: =SUM(O10:O32) -> 0
A10: An Toàn | B10: Trang thiết bị bảo hộ lao động | C10: Thiết bị thi công, công cụ, dụng cụ đảm bảo tiêu chuẩn an toàn | D10: Các thiết bị thi công phải đúng kỹ thuật, không sử dụng thiết bị hư hỏng làm ảnh hưởng đến chất lượng và thẩm mỹ. | E10: P.AU-KPI 1 | F10: Số lần vi phạm / tháng (kiểm tra 2 lần/ ngày) | G10: 0.15 | I10: 0 Lần / Tháng | J10: 1 Lần/Tháng | K10: 0 Lần / Tháng | L10: 0 | M10: =IF(SUM(L12:L15)>=1,$G$10,0) -> 0 | N10: 0 | O10: =IF(SUM(N12:N15)>=1,$G$10,0) -> 0
C11: Được trang bị đầy đủ đồ bảo hộ lao động | D11: Trang bị đầy đủ đồ bảo hộ lao động khi làm việc tại công trường theo quy định | F11: Số lần không trang bị đầy đủ đồ bảo hộ lao động | I11: 0 Lần / Tháng | J11: 1 Lần/Tháng | K11: 0 Lần / Tháng | L11: 0 | N11: 0
C12: Trang bị đầy đủ trang thiết bị an toàn đúng, đủ với tính chất công việc thực hiện | D12: Trang bị bảo hộ lao động đầy đủ cho nhân viên, công nhân thi công | F12: Số lần vi phạm / tháng (kiểm tra 2 lần/ ngày) | I12: 0 Lần / Tháng | J12: 1 Lần/Tháng | K12: 0 Lần / Tháng | L12: 0 | N12: 0
C13: Thiết bị thi công cụ dụng cụ đảm bảo tiêu chuẩn | D13: Nội quy công trường: an toàn, cấm hút thuốc.v.v.. | F13: Số lần kiểm tra 2 lần/ ngày | I13: 0 Lần / Tháng | J13: 1 Lần/Tháng | K13: 0 Lần / Tháng | L13: 0 | N13: 0
D14: Thiết bị, công cụ dụng cụ thi công có kiểm định, kiểm tra định kỳ và còn hiệu lực | F14: Số lần vi phạm / tháng (kiểm tra 1 lần/ tháng) | I14: 0 Lần / Tháng | J14: 1 Lần/Tháng | K14: 0 Lần / Tháng | L14: 0 | N14: 0
B15: Đảm bảo an toàn trong công việc | C15: Không xảy ra nguy cơ tai nạn lao động tại công trình | D15: Không xảy ra tai nạn lao động tại nơi làm việc, công trường | F15: Số lần tai nạn trong tháng | I15: 0 Lần / Tháng | J15: 1 Lần/Tháng | K15: 0 Lần / Tháng | L15: 0 | N15: 0
C16: Tuyệt đối không hút thuốc trong công trình | D16: Cấm tuyệt đối hút thuốc tại công trường | F16: Số lần hút thuốc tại cộng trình | I16: 0 Lần / Tháng | J16: 1 Lần/Tháng | K16: 0 Lần / Tháng | L16: 0 | N16: 0
A17: Kỹ thuật/ Chất lượng | B17: Lập trình hệ thống đúng yêu cầu của khách hàng | C17: Sự hài lòng của khách hàng Sản phẩm đạt chất lượng kỹ thuật | D17: Thực hiện công việc lập trình không đúng Control Panel hoặc lập bảng Control Panel không đúng yêu cầu của khách hàng dẫn đến phải sửa đổi chương trình/ cài đặt nhiều hơn 1 lần. | E17: P.AU-KPI 2 | F17: Số lần phát sinh thay đổi viết lại chương trình cho một công đoạn nhiều hơn 1 lần trong 01 tháng. | G17: 0.2 | I17: 0 Lỗi / DA/ Việc | J17: 1 Lỗi / DA/việc | K17: 0 Lỗi / DA/việc | L17: 0 | M17: =IF(SUM(L17:L18)>=1,$G$17,0) -> 0 | N17: 0 | O17: =IF(SUM(N17:N18)>=1,$G$17,0) -> 0
B18: Thi công lắp đặt, cài đặt/ sửa chữa đạt tiêu chuẩn kỹ thuật, chất lượng | C18: Chất lượng lắp đặt, cài đặt, hiệu chỉnh | D18: Thi công, lắp đặt cài đặt sửa chữa đúng nguyên lý, đúng kỹ thuật, đúng bản vẽ, đảm bảo về thẩm mỹ kỹ thuật | F18: Số lỗi thi công, cài đặt sữa chữa không đúng thiết kế gây ra hư hỏng, hoặc khách hàng phản ánh trong 01 tháng | I18: 0 Lỗi / DA/ Việc | J18: 1 Lỗi / DA/việc | K18: 0 Lỗi / DA/việc | L18: 0 | N18: 0
A19: Qui trình | B19: Quy trình và quản lý chất lượng | C19: Quy trình và quản lý An toàn, chất lượng, Kỹ thuật | D19: Áp dụng qui trình cho từng công đoạn của công việc | E19: P.AU-KPI 3 | F19: Số lần không áp dụng qui trình/ tháng | G19: 0.15 | I19: 0 | J19: 1 | K19: 0 | L19: 0 | M19: =IF(SUM(L19:L21)>=1,$G$19,0) -> 0 | N19: 0 | O19: =IF(SUM(N19:N21)>=1,$G$19,0) -> 0
C20: Hiệu suất | D20: Đề xuất phương án thực hiện | F20: Phương án/ giải pháp thực hiện công việc | I20: 3 phương án | J20: 1 | K20: 3 phương án, có 1 phuong án tối ưu/ 1 sự việc | L20: 0 | N20: 0
D21: Qui trình 5S | F21: Số lần vi phạm/ ko thực hiện/tháng | I21: 0 | J21: 1 Lần | K21: 0 | L21: 0 | N21: 0
A22: Tiến độ | B22: Tiến độ hoàn thành công việc | C22: Tiến độ thực hiện công việc | D22: Thực hiện công việc nhanh chóng không ì ạch, không tập trung, chậm trễ tiến độ chung với dự án | E22: P.AU-KPI 4 | F22: Số lần trễ tiến độ /dự án | G22: 0.15 | I22: 0 Lần | J22: 1 | K22: 0 Lần | L22: 0 | M22: =IF(SUM(L22:L23)>=1,$G$22,0) -> 0 | N22: 0 | O22: =IF(SUM(N22:N23)>=1,$G$22,0) -> 0
D23: Báo cáo đúng hạn, đầy đủ thông tin | F23: Số lần báo cáo không kịp thời, không đạt yêu cầu/tháng | I23: 0 Lần | J23: 1 | K23: 0 Lần | L23: 0 | N23: 0
A24: Chi Phí | B24: Giới hạn chi phí phát sinh thay đổi | C24: Giảm chi phí tối thiểu | D24: Thực hiện công việc không triệt để, dẫn đến thực hiện một công việc ở công trình nhiều hơn 1 lần | E24: P.AU-KPI 5 | F24: Giới hạn PS chi phí +/- 2% | G24: 0.15 | I24: 0.01 | J24: <2%, >2% | K24: </= 1% | L24: 0 | M24: =IF(SUM(L24:L26)>=1,$G$24,0) -> 0 | N24: 0 | O24: =IF(SUM(N24:N26)>=1,$G$24,0) -> 0
D25: Khảo sát, đo đạc, thiết kế bản vẽ theo thực tế thi công dự án 100% | F25: Sai lệch so với thực tế thi công +/- 2% | I25: 0.01 | J25: <2%, >2% | K25: </= 1% | L25: 0 | N25: 0
D26: Thực tế thi công, Lập bảng quản lí hàng hóa, vật tư theo dự án hiệu quả | F26: <=1-2% giá trị /dự án | I26: 0.01 | J26: <2%, >2% | K26: </= 1% | L26: 0 | N26: 0
D27: Làm mất mát, thất thoát vật tư tại nơi làm việc | F27: Số lần làm mất mát thất thoát vật tư | I27: 0 Lần | J27: 1 Lần | K27: 0 Lần | L27: 0 | N27: 0
D28: Cắt dây điện đúng kích thước, sai số cho phép theo quy định | F28: Sai lệch so với thực tế thi công +/- 2% | I28: 0.01 | J28: <2%, >2% | K28: </= 1% | L28: 0 | N28: 0
A29: Đào tạo và Phẫm chất | B29: Đào tạo nhân sự | C29: Tham gia 100% các buổi training do phòng ban tổ chức | D29: Tham dự đào tạo và nhận kết quả đào tạo theo kế hoạch đào tạo của phòng ban | E29: P.AU-KPI 6 | F29: % số khóa đào tạo thực hiện/kế hoạch | G29: 0.15 | I29: >80% | J29: <80% | K29: 100% | L29: 0 | M29: =IF(SUM(L29:L31)>=1,$G$29,0) -> 0 | N29: 0 | O29: =IF(SUM(N29:N31)>=1,$G$29,0) -> 0
D30: Tham gia training From fails ít nhất 01 lần/ tháng | F30: % nhân sự đạt yêu cầu /tổng số nhân viên phòng ban | I30: >80% | J30: <80% | K30: 100% | L30: 0 | N30: 0
B31: Tuân thủ nội quy quy chế công ty | C31: Nội quy công ty, nội quy công trình | D31: Tuân thủ nội quy công ty, nội quy công trình | F31: Số lần vi phạm /tháng | I31: 0 lần / tháng | J31: 2lần / tháng | K31: 0 lần / tháng | L31: 0 | N31: 0
A32: Thẩm Mỹ | B32: Sản phẩm, Dịch vụ | C32: Tiêu chí đạt thẩm mỹ | D32: Không có phàn nàn từ khách hàng hoặc các cấp quản lý về chất lượng thẩm mỹ của dự án đang thực hiện | E32: P.AU-KPI 7 | F32: Số lần phàn nàn về chất lượng, thẩm mỹ | G32: 0.05 | I32: 0 | J32: 1 | K32: 0 | L32: 0 | M32: =IF(SUM(L32:L32)>=1,$G$32,0) -> 0 | N32: 0 | O32: =IF(SUM(N32:N32)>=1,$G$32,0) -> 0

Sheet P3.1.2 (KPI Leader)
C1: QUẢN TRỊ HIỆU SUẤT | D1: ='P3.1.2 (Staff)'!D1:H2 -> CÔNG TY TNHH KỸ THUẬT TỰ ĐỘNG AN DƯƠNG BẢNG KPI NHÂN VIÊN THÁNG 6 NĂM 2024
C3: Căn cứ quy định đánh giá hiệu quả công việc hiện hành
C4: Căn cứ kế hoạch phát triển công ty
A6: Phòng Tự Động | B6: Mục tiêu chiến lược | C6: Yếu tố quyết định thành công | D6: Chỉ tiêu đánh giá (KPI) | E6: Stt KPI | F6: Đơn vị đo lường | G6: Trọng số (%) | I6: Mục tiêu 2024 | J6: Kém | K6: Xuất sắc | L6: Điểm Đánh Giá
L7: Họ và tên
H8: Thực hiện cùng kỳ 2023 | L8: Số lần vi phạm | M8: Điểm thưởng bị trừ
A9: TỔNG CỘNG | G9: =SUM(G10:G33) -> 1 | L9: =SUM(L12:L33) -> 0 | M9: =SUM(M10:M33) -> 0
A10: An Toàn | B10: Trang thiết bị bảo hộ lao động | C10: Thiết bị thi công, công cụ, dụng cụ đảm bảo tiêu chuẩn an toàn | D10: Các thiết bị thi công phải đúng kỹ thuật, không sử dụng thiết bị hư hỏng làm ảnh hưởng đến chất lượng và thẩm mỹ. | E10: P.AU-KPI 1 | F10: Số lần vi phạm / tháng (kiểm tra 2 lần/ ngày) | G10: 0.15 | I10: 0 Lần / Tháng | J10: 1 Lần/Tháng | K10: 0 Lần / Tháng | L10: 0 | M10: =IF(SUM(L12:L15)>=1,$G$10,0) -> 0
C11: Được trang bị đầy đủ đồ bảo hộ lao động | D11: Trang bị đầy đủ đồ bảo hộ lao động khi làm việc tại công trường theo quy định | F11: Số lần không trang bị đầy đủ đồ bảo hộ lao động | I11: 0 Lần / Tháng | J11: 1 Lần/Tháng | K11: 0 Lần / Tháng | L11: 0
C12: Trang bị đầy đủ trang thiết bị an toàn đúng, đủ với tính chất công việc thực hiện | D12: Trang bị bảo hộ lao động đầy đủ cho nhân viên, công nhân thi công | F12: Số lần vi phạm / tháng (kiểm tra 2 lần/ ngày) | I12: 0 Lần / Tháng | J12: 1 Lần/Tháng | K12: 0 Lần / Tháng | L12: 0
C13: Thiết bị thi công cụ dụng cụ đảm bảo tiêu chuẩn | D13: Nội quy công trường: an toàn, cấm hút thuốc.v.v.. | F13: Số lần kiểm tra 2 lần/ ngày | I13: 0 Lần / Tháng | J13: 1 Lần/Tháng | K13: 0 Lần / Tháng | L13: 0
D14: Thiết bị, công cụ dụng cụ thi công có kiểm định, kiểm tra định kỳ và còn hiệu lực | F14: Số lần vi phạm / tháng (kiểm tra 1 lần/ tháng) | I14: 0 Lần / Tháng | J14: 1 Lần/Tháng | K14: 0 Lần / Tháng | L14: 0
C15: Đảm bảo nơi làm việc, công trường | D15: Không xảy ra tai nạn lao động tại nơi làm việc, công trường | F15: Số lần tai nạn trong tháng | I15: 0 Lần / Tháng | J15: 1 Lần/Tháng | K15: 0 Lần / Tháng | L15: 0
A16: Kỹ thuật/ Chất lượng | B16: Lập trình hệ thống đúng yêu cầu của khách hàng | C16: Sự hài lòng của khách hàng Sản phẩm đạt chất lượng kỹ thuật | D16: Thực hiện công việc lập trình không đúng Control Panel hoặc lập bảng Control Panel không đúng yêu cầu của khách hàng dẫn đến phải sửa đổi chương trình/ cài đặt nhiều hơn 1 lần. | E16: P.AU-KPI 2 | F16: Số lần phát sinh thay đổi viết lại chương trình cho một công đoạn nhiều hơn 1 lần trong 01 tháng. | G16: 0.2 | I16: 0 Lỗi / DA/ Việc | J16: 1 Lỗi / DA/việc | K16: 0 Lỗi / DA/việc | L16: 0 | M16: =IF(SUM(L16:L17)>=1,$G$16,0) -> 0
B17: Thi công lắp đặt, cài đặt/ sửa chữa đạt tiêu chuẩn kỹ thuật, chất lượng | C17: Chất lượng lắp đặt, cài đặt, hiệu chỉnh | D17: Thi công, lắp đặt cài đặt sửa chữa đúng nguyên lý, đúng kỹ thuật, đúng bản vẽ, đảm bảo về thẩm mỹ kỹ thuật | F17: Số lỗi thi công, cài đặt sữa chữa không đúng thiết kế gây ra hư hỏng, hoặc khách hàng phản ánh trong 01 tháng | I17: 0 Lỗi / DA/ Việc | J17: 1 Lỗi / DA/việc | K17: 0 Lỗi / DA/việc | L17: 0
B18: Bốc BOM thiết bị đúng tiêu chuẩn kỹ thuật, hàng hóa thông dụng, giá cả phải chăng | C18: BOM thiết bị hàng hóa thông dụng giá hợp lý | D18: Bốc BOM thiết bị đúng tiêu chuẩn kỹ thuật, hàng hóa thông dụng giá cả phải chăng | F18: Số lần bốc BOM không đúng tiêu chuẩn kỹ thuật, hàng hóa thông dụng | I18: 0 Lỗi / DA/ Việc | J18: 1 Lỗi / DA/việc | K18: 0 Lỗi / DA/việc
A19: Qui trình | B19: Quy trình và quản lý chất lượng | C19: Quy trình và quản lý An toàn, chất lượng, Kỹ thuật | D19: Áp dụng qui trình cho từng công đoạn của công việc | E19: P.AU-KPI 3 | F19: Số lần không áp dụng qui trình/ tháng | G19: 0.15 | I19: 0 | J19: 1 | K19: 0 | L19: 0 | M19: =IF(SUM(L19:L22)>=1,$G$19,0) -> 0
C20: Hiệu suất | D20: Đề xuất phương án thực hiện | F20: Phương án/ giải pháp thực hiện công việc | I20: 3 phương án | J20: 1 | K20: 3 phương án, có 1 phuong án tối ưu/ 1 sự việc | L20: 0
D21: Cải tiến sản phẩm, Kaizen | F21: Số lần /tháng | I21: 1 Lần | J21: 0 Lần | K21: > 2 Lần | L21: 0
D22: Qui trình 5S | F22: Số lần vi phạm/ ko thực hiện/tháng | I22: 0 | J22: 1 Lần | K22: 0 | L22: 0
A23: Tiến độ | B23: Tiến độ hoàn thành công việc | C23: Tiến độ thực hiện công việc | D23: Thực hiện công việc nhanh chóng không ì ạch, không tập trung, chậm trễ tiến độ chung với dự án | E23: P.AU-KPI 4 | F23: Số lần trễ tiến độ /dự án | G23: 0.15 | I23: 0 Lần | J23: 1 | K23: 0 Lần | L23: 0 | M23: =IF(SUM(L23:L24)>=1,$G$23,0) -> 0
D24: Báo cáo đúng hạn, đầy đủ thông tin | F24: Số lần báo cáo không kịp thời, không đạt yêu cầu/tháng | I24: 0 Lần | J24: 1 | K24: 0 Lần | L24: 0
A25: Chi Phí | B25: Giới hạn chi phí phát sinh thay đổi | C25: Giảm chi phí tối thiểu | D25: Thực hiện công việc không triệt để, dẫn đến thực hiện một công việc ở công trình nhiều hơn 1 lần | E25: P.AU-KPI 5 | F25: Giới hạn PS chi phí +/- 2% | G25: 0.15 | I25: 0.01 | J25: <2%, >2% | K25: </= 1% | L25: 0 | M25: =IF(SUM(L25:L27)>=1,$G$25,0) -> 0
D26: Khảo sát, đo đạc, thiết kế bản vẽ theo thực tế thi công dự án 100% | F26: Sai lệch so với thực tế thi công +/- 2% | I26: 0.01 | J26: <2%, >2% | K26: </= 1% | L26: 0
D27: Thực tế thi công, Lập bảng quản lí hàng hóa, vật tư theo dự án hiệu quả | F27: <=1-2% giá trị /dự án | I27: 0.01 | J27: <2%, >2% | K27: </= 1% | L27: 0
D28: Làm mất mát, thất thoát vật tư tại nơi làm việc | F28: Số lần làm mất mát thất thoát vật tư | I28: 0 Lần | J28: 1 Lần | K28: 0 Lần
D29: Cắt dây điện đúng kích thước, sai số cho phép theo quy định | F29: Sai lệch so với thực tế thi công +/- 2% | I29: 0.01 | J29: <2%, >2% | K29: </= 1%
A30: Đào tạo và Phẫm chất | B30: Đào tạo nhân sự | C30: Đào tạo nhân viên theo kế hoạch đào tạo | D30: Số khóa đào tạo /người | E30: P.AU-KPI 6 | F30: % số khóa đào tạo thực hiện/kế hoạch | G30: 0.15 | I30: >80% | J30: <80% | K30: 100% | L30: 0 | M30: =IF(SUM(L30:L32)>=1,$G$30,0) -> 0
D31: Chất lượng nhân sự đáp ứng nhu cầu | F31: % nhân sự đạt yêu cầu /tổng số nhân viên phòng ban | I31: >80% | J31: <80% | K31: 100% | L31: 0
B32: Tuân thủ nội quy quy chế công ty | C32: Nội quy công ty, nội quy công trình | D32: Nội quy công ty, nội quy công trình | F32: Số lần vi phạm /tháng | I32: 0 lần / tháng | J32: 2lần / tháng | K32: 0 lần / tháng | L32: 0
A33: Thẩm Mỹ& Chi phí | B33: Sản phẩm, Dịch vụ | C33: Tiêu chí đạt thẩm mỹ | D33: 2 /3 ý kiến đánh giá đạt trong đó có 1 ý kiến khách hàng ( Cấp giám đốc nhà máy trở lên ) | E33: P.AU-KPI 7 | F33: 2/3 ý kiến /sản phẩm | G33: 0.05 | I33: >80% | J33: <80% | K33: 90% | L33: 0 | M33: =IF(SUM(L33:L33)>=1,$G$33,0) -> 0

Sheet P3.1.2 (KPI Phòng Ban)
C1: QUẢN TRỊ HIỆU SUẤT | D1: CÔNG TY TNHH KỸ THUẬT TỰ ĐỘNG AN DƯƠNG BẢNG KPI PHÒNG TỰ ĐỘNG THÁNG 04 NĂM 2026 | L1: NHÂN XÉT CỦA QUẢN TRỊ HIỆU XUẤT
C3: Căn cứ quy định đánh giá hiệu quả công việc hiện hành | F3: Người đánh giá : | G3: NGUYỄN PHƯỚC TÂN
C4: Căn cứ kế hoạch phát triển công ty
A6: Phòng Tự Động | B6: Mục tiêu chiến lược | C6: Yếu tố quyết định thành công | D6: Chỉ tiêu đánh giá (KPI) | E6: Stt KPI | F6: Đơn vị đo lường | G6: Trọng số (%) | I6: Mục tiêu 2026 | J6: Kém | K6: Xuất sắc | O6: Điểm Đánh Giá
O7: Manager: Lê Công Dũng
H8: Thực hiện cùng kỳ 2023 | L8: Phân loại KPI ? | M8: Tính kiểm soát ? | N8: Mức độ tương thích giữa các chỉ số đạt được với mục tiêu chiến lược | O8: Số lần vi phạm | P8: Điểm thưởng bị trừ
A9: TỔNG CỘNG | G9: =SUM(G10:G35) -> 1 | O9: =SUM(O12:O35) -> 1 | P9: =SUM(P10:P35) -> 0.15
A10: An Toàn | B10: Trang thiết bị bảo hộ lao động | C10: Thiết bị thi công, công cụ, dụng cụ đảm bảo tiêu chuẩn an toàn | D10: Các thiết bị thi công phải đúng kỹ thuật, không sử dụng thiết bị hư hỏng làm ảnh hưởng đến chất lượng và thẩm mỹ. | E10: P.AU-KPI 1 | F10: Số lần vi phạm / tháng (kiểm tra 2 lần/ ngày) | G10: 0.15 | I10: 0 Lần / Tháng | J10: 1 Lần/Tháng | K10: 0 Lần / Tháng | O10: 0 | P10: =IF(SUM(O10:O16)>=1,$G$10,0) -> 0.15
C11: Được trang bị đầy đủ đồ bảo hộ lao động | D11: Trang bị đầy đủ đồ bảo hộ lao động khi làm việc tại công trường theo quy định | F11: Số lần không trang bị đầy đủ đồ bảo hộ lao động | I11: 0 Lần / Tháng | J11: 1 Lần/Tháng | K11: 0 Lần / Tháng | O11: 0
C12: Trang bị đầy đủ trang thiết bị an toàn đúng, đủ với tính chất công việc thực hiện | D12: Trang bị bảo hộ lao động đầy đủ cho nhân viên, công nhân thi công | F12: Số lần vi phạm / tháng (kiểm tra 2 lần/ ngày) | I12: 0 Lần / Tháng | J12: 1 Lần/Tháng | K12: 0 Lần / Tháng | L12: KPI | M12: Đo lường hàng tháng | N12: Tương đối | O12: 0
C13: Thiết bị thi công cụ dụng cụ đảm bảo tiêu chuẩn | D13: Nội quy công trường: an toàn, cấm hút thuốc.v.v.. | F13: Số lần kiểm tra 2 lần/ ngày | I13: 0 Lần / Tháng | J13: 1 Lần/Tháng | K13: 0 Lần / Tháng | L13: KPI | M13: Đo lường hàng tháng | N13: Tương đối | O13: 0
D14: Thiết bị, công cụ dụng cụ thi công có kiểm định, kiểm tra định kỳ và còn hiệu lực | F14: Số lần vi phạm / tháng (kiểm tra 1 lần/ tháng) | I14: 0 Lần / Tháng | J14: 1 Lần/Tháng | K14: 0 Lần / Tháng | O14: 0
B15: Đảm bảo an toàn trong công việc | C15: Phân tích, đánh giá rủi ro, phương pháp làm việc an toàn khi thực hiện | D15: Lập bảng phân tích, đánh giá rủi ro, biện pháp phòng ngừa | F15: Số lần vi phạm / hạn mục (kiểm tra bất kỳ thời gian DA) | I15: 0 Lần / Tháng | J15: 1 Lần/Tháng | K15: 0 Lần / Tháng | L15: KPI | M15: Đo lường hàng tháng | N15: Tương đối | O15: 1
C16: Đảm bảo nơi làm việc, công trường | D16: Không xảy ra tai nạn lao động tại nơi làm việc, công trường | F16: Số lần tai nạn trong tháng | I16: 0 Lần / Tháng | J16: 1 Lần/Tháng | K16: 0 Lần / Tháng | L16: KPI | M16: Đo lường hàng tháng | N16: Tương đối | O16: 0
A17: Kỹ thuật/ Chất lượng | B17: Lập trình hệ thống đúng yêu cầu của khách hàng | C17: Sự hài lòng của khách hàng Sản phẩm đạt chất lượng kỹ thuật | D17: Thực hiện công việc lập trình không đúng Control Panel hoặc lập bảng Control Panel không đúng yêu cầu của khách hàng dẫn đến phải sửa đổi chương trình/ cài đặt nhiều hơn 1 lần. | E17: P.AU-KPI 2 | F17: Số lần phát sinh thay đổi viết lại chương trình cho một công đoạn nhiều hơn 1 lần trong 01 tháng. | G17: 0.2 | I17: 0 Lỗi / DA/ Việc | J17: 1 Lỗi / DA/việc | K17: 0 Lỗi / DA/việc | L17: KPI | M17: Đo lường hàng tháng | N17: Tương đối | O17: 0 | P17: =IF(SUM(O17:O19)>=1,$G$17,0) -> 0
B18: Thi công lắp đặt, cài đặt/ sửa chữa đạt tiêu chuẩn kỹ thuật, chất lượng | C18: Chất lượng lắp đặt, cài đặt, hiệu chỉnh | D18: Thi công, lắp đặt cài đặt sửa chữa đúng nguyên lý, đúng kỹ thuật, đúng bản vẽ, đảm bảo về thẩm mỹ kỹ thuật | F18: Số lỗi thi công, cài đặt sữa chữa không đúng thiết kế gây ra hư hỏng, hoặc khách hàng phản ánh trong 01 tháng | I18: 0 Lỗi / DA/ Việc | J18: 1 Lỗi / DA/việc | K18: 0 Lỗi / DA/việc | L18: KPI | M18: Đo lường hàng tháng | N18: Tương đối | O18: 0
B19: Bốc BOM thiết bị đúng tiêu chuẩn kỹ thuật, hàng hóa thông dụng, giá cả phải chăng | C19: BOM thiết bị hàng hóa thông dụng giá hợp lý | D19: Bốc BOM thiết bị đúng tiêu chuẩn kỹ thuật, hàng hóa thông dụng giá cả phải chăng | F19: Số lần bốc BOM thiết bị không đúng tiêu chuẩn kỹ thuật, hàng hóa không thông dụng và giá cao bị cấp trên phản ánh | I19: 0 Lỗi / DA/ Việc | J19: 1 Lỗi / DA/việc | K19: 0 Lỗi / DA/việc | O19: 0
A20: Qui trình | B20: Quy trình và quản lý chất lượng | C20: Quy trình và quản lý An toàn, chất lượng, Kỹ thuật | D20: Áp dụng qui trình cho từng công đoạn của công việc | E20: P.AU-KPI 3 | F20: Số lần không áp dụng qui trình/ tháng | G20: 0.15 | I20: 0 | J20: 1 | K20: 0 | L20: KPI | M20: Đo lường hàng tháng | N20: Tương đối | O20: 0 | P20: =IF(SUM(O20:O23)>=1,$G$20,0) -> 0
C21: Hiệu suất | D21: Đề xuất phương án thực hiện | F21: Phương án/ giải pháp thực hiện công việc | I21: 3 phương án | J21: 1 | K21: 3 phương án, có 1 phuong án tối ưu/ 1 sự việc | L21: KPI | M21: Đo lường hàng tháng | N21: Tương đối | O21: 0
D22: Cải tiến sản phẩm, Kaizen | F22: Số lần /tháng | I22: 1 Lần | J22: 0 Lần | K22: > 2 Lần | O22: 0
D23: Qui trình 5S | F23: Số lần vi phạm/ ko thực hiện/tháng | I23: 0 | J23: 1 Lần | K23: 0 | L23: KPI | M23: Đo lường hàng tháng | N23: Tương đối | O23: 0
A24: Tiến độ | B24: Tiến độ hoàn thành công việc | C24: Tiến độ thực hiện công việc | D24: Thực hiện công việc nhanh chóng không ì ạch, không tập trung, chậm trễ tiến độ chung với dự án | E24: P.AU-KPI 4 | F24: Số lần trễ tiến độ /dự án | G24: 0.15 | I24: 0 Lần | J24: 1 | K24: 0 Lần | L24: KPI | M24: Đo lường hàng tháng | N24: Tương đối | O24: 0 | P24: =IF(SUM(O24:O25)>=1,$G$24,0) -> 0
D25: Báo cáo đúng hạn, đầy đủ thông tin | F25: Số lần báo cáo không kịp thời, không đạt yêu cầu/tháng | I25: 0 Lần | J25: 1 | K25: 0 Lần | O25: 0
A26: Chi Phí | B26: Giới hạn chi phí phát sinh thay đổi | C26: Giảm chi phí tối thiểu | D26: Thực hiện công việc không triệt để, dẫn đến thực hiện một công việc ở công trình nhiều hơn 1 lần | E26: P.AU-KPI 5 | F26: Giới hạn PS chi phí +/- 2% | G26: 0.15 | I26: 0.01 | J26: <2%, >2% | K26: </= 1% | L26: KPI | O26: 0 | P26: =IF(SUM(O26:O30)>=1,$G$26,0) -> 0
D27: Khảo sát, đo đạc, thiết kế bản vẽ theo thực tế thi công dự án 100% | F27: Sai lệch so với thực tế thi công +/- 2% | I27: 0.01 | J27: <2%, >2% | K27: </= 1% | L27: KPI | O27: 0
D28: Thực tế thi công, Lập bảng quản lí hàng hóa, vật tư theo dự án hiệu quả | F28: <=1-2% giá trị /dự án | I28: 0.01 | J28: <2%, >2% | K28: </= 1% | L28: KPI | O28: 0
D29: Làm mất mát, thất thoát vật tư tại nơi làm việc | F29: Số lần làm mất mát thất thoát vật tư | I29: 0 Lần | J29: 1 Lần | K29: 0 Lần | O29: 0
D30: Cắt dây điện đúng kích thước, sai số cho phép theo quy định | F30: Sai lệch so với thực tế thi công +/- 2% | I30: 0.01 | J30: <2%, >2% | K30: </= 1% | O30: 0
A31: Đào tạo và Phẫm chất | B31: Đào tạo nhân sự | C31: Đào tạo nhân viên theo kế hoạch đào tạo | D31: Số khóa đào tạo /người | E31: P.AU-KPI 6 | F31: % số khóa đào tạo thực hiện/kế hoạch | G31: 0.15 | I31: >80% | J31: <80% | K31: 100% | L31: KPI | M31: Đo lường hàng tháng | N31: Tương đối | O31: 0 | P31: =IF(SUM(O31:O34)>=1,$G$31,0) -> 0
D32: Chất lượng nhân sự đáp ứng nhu cầu | F32: % nhân sự đạt yêu cầu /tổng số nhân viên phòng ban | I32: >80% | J32: <80% | K32: 100% | L32: KPI | M32: Đo lường hàng tháng | N32: Tương đối | O32: 0
D33: Training form fails ít nhất 01 lần/ tháng | F33: Số lần thực hiện/ tháng | I33: 1 lần/tháng | J33: 0 lần/ tháng | K33: 2 lần/ tháng | O33: 0
B34: Tuân thủ nội quy quy chế công ty | C34: Nội quy công ty, nội quy công trình | D34: Nội quy công ty, nội quy công trình | F34: Số lần vi phạm /tháng | I34: 0 lần / tháng | J34: 2lần / tháng | K34: 0 lần / tháng | L34: KPI | M34: Đo lường hàng tháng | N34: Tương đối | O34: 0
A35: Thẩm Mỹ& Chi phí | B35: Sản phẩm, Dịch vụ | C35: Tiêu chí đạt thẩm mỹ | D35: 2 /3 ý kiến đánh giá đạt trong đó có 1 ý kiến khách hàng ( Cấp giám đốc nhà máy trở lên ) | E35: P.AU-KPI 7 | F35: 2/3 ý kiến /sản phẩm | G35: 0.05 | I35: >80% | J35: <80% | K35: 90% | L35: KPI | M35: Đo lường hàng tháng | N35: Tương đối | O35: 0 | P35: =IF(SUM(O35:O35)>=1,$G$35,0) -> 0

Sheet Kết Quả Đánh Giá 3P
D2: BẢNG ĐÁNH GIÁ THEO PHƯƠNG PHÁP 3P | AO2: No. AUT. Date: 30/ 04/2026 Page: 01/01
C6: I | D6: THÔNG TIN CHUNG
D7: Bộ phận được đánh giá: | E7: TỰ ĐỘNG HÓA
D8: Tháng đánh giá: | E8: T04/2026
D9: Người đánh giá: | E9: Lê Công Dũng
D10: Tiêu chí đánh giá | E10: Phương pháp 3P với trọng số
C12: II | D12: BẢNG TỔNG HỢP KẾT QUẢ
C13: STT | D13: Mã nhân viên | E13: Họ và tên | F13: Chức vụ | G13: TIÊU CHÍ P1 (lương theo vị trí) | I13: TIÊU CHÍ P2 (lương theo năng lực) | AF13: TIÊU CHÍ P3 (lương theo hiệu quả công việc)
G14: P1.1 (lương cơ bản) | H14: P1.2 (lương chuyên môn, chức vụ) Đánh giá theo định kỳ | I14: P2.1 (lương theo kiến thức công việc) Đánh giá theo định kỳ | O14: P2.2 (lương theo kỹ năng, kinh nghiệm) Đánh giá theo định kỳ | AF14: P3.1 | AN14: P3.2 (theo doanh thu)
AF15: P3.1.1 KPI CÁ NHÂN (1) | AI15: P3.1.2 KPI PHÒNG BAN (2) | AL15: KPI NHÂN VIÊN = (1) X (2) | AO15: Ghi chú
G16: Mức lương | H16: Mức lương | I16: TC1 | J16: TC2 | K16: TC3 | L16: TC4 | M16: TC5 | N16: Hệ Số | O16: TC1 | P16: TC2 | Q16: TC3 | R16: TC4 | S16: TC5 | T16: TC6 | U16: TC7 | V16: TC8 | W16: TC9 | X16: TC10 | Y16: TC11 | Z16: TC12 | AA16: TC13 | AB16: TC14 | AC16: TC15 | AD16: TC16 | AE16: Hệ Số | AF16: Điểm thưởng bị trừ | AG16: Điểm | AH16: Trọng số: 0.6 | AI16: Điểm thưởng bị trừ | AJ16: Điểm | AK16: Trọng số: 0.4 | AL16: Tổng trọng số | AM16: Hệ số | AN16: Hệ số
C17: 1 | D17: E504 | E17: Hồ Hữu Thanh Sơn | F17: Leader | G17: Dành cho kế toán | H17: Dành cho kế toán | I17: ='P2.1(Kiến Thức)'!F7 -> 34 | J17: ='P2.1(Kiến Thức)'!F41 -> 32 | K17: ='P2.1(Kiến Thức)'!F132 -> 15 | L17: ='P2.1(Kiến Thức)'!F217 -> 5 | M17: ='P2.1(Kiến Thức)'!F224 -> 5 | N17: 0.7 | O17: ='P2.2 (Kỹ Năng chuyên Môn)'!E15 -> 7 | P17: ='P2.2 (Kỹ Năng chuyên Môn)'!F15 -> 6 | Q17: ='P2.2 (Kỹ Năng chuyên Môn)'!G15 -> 6 | R17: ='P2.2 (Kỹ Năng chuyên Môn)'!H15 -> 8 | S17: ='P2.2 (Kỹ Năng chuyên Môn)'!I15 -> 8 | T17: ='P2.2 (Kỹ Năng chuyên Môn)'!J15 -> 6 | U17: ='P2.2 (Kỹ Năng chuyên Môn)'!K15 -> 6 | V17: ='P2.2 (Kỹ Năng chuyên Môn)'!L15 -> 6 | ... AD17: ='P2.2 (Kỹ Năng chuyên Môn)'!T15 -> 4 | AE17: =SUM(O17:AD17)/100 -> 0.93 | AF17: ='P3.1.1 (KPI Senior)'!M9 -> 0 | AG17: =100%-AF17 -> 1 | AH17: =AG17*0.6 -> 0.6 | AI17: ='P3.1.2 (KPI Phòng Ban)'!P9 -> 0.15 | AJ17: =100%-AI17 -> 0.85 | AK17: =AJ17*0.4 -> 0.34 | AL17: =AH17+AK17 -> 0.94 | AM17: =IF(AL17>=1,1,IF(AL17>=0.9,0.8,IF(AL17>=0.8,0.7,IF(AL17>=0.7,0.5,0)))) -> 0.8 | AN17: Dành cho kế toán
C18: 2 | D18: E502 | E18: Tăng Phú Vinh | F18: Staff | G18: Dành cho kế toán | H18: Dành cho kế toán | I18: ='P2.1(Kiến Thức)'!G7 -> 14 | J18: ='P2.1(Kiến Thức)'!G41 -> 14 | K18: ='P2.1(Kiến Thức)'!G132 -> 15 | L18: ='P2.1(Kiến Thức)'!G217 -> 5 | M18: ='P2.1(Kiến Thức)'!G224 -> 5 | N18: =SUM(I18:M18)/100 -> 0.53 | O18: ='P2.2 (Kỹ Năng chuyên Môn)'!E16 -> 5 | P18: ='P2.2 (Kỹ Năng chuyên Môn)'!F16 -> 5 | Q18: ='P2.2 (Kỹ Năng chuyên Môn)'!G16 -> 6 | R18: ='P2.2 (Kỹ Năng chuyên Môn)'!H16 -> 7 | S18: ='P2.2 (Kỹ Năng chuyên Môn)'!I16 -> 7 | T18: ='P2.2 (Kỹ Năng chuyên Môn)'!J16 -> 6 | U18: ='P2.2 (Kỹ Năng chuyên Môn)'!K16 -> 6 | V18: ='P2.2 (Kỹ Năng chuyên Môn)'!L16 -> 6 | ... AD18: ='P2.2 (Kỹ Năng chuyên Môn)'!T16 -> 4 | AE18: =SUM(O18:AD18)/100 -> 0.87 | AF18: ='P3.1.1 (KPI Senior)'!M10 -> 0 | AG18: =100%-AF18 -> 1 | AH18: =AG18*0.6 -> 0.6 | AI18: ='P3.1.2 (KPI Phòng Ban)'!P9 -> 0.15 | AJ18: =100%-AI18 -> 0.85 | AK18: =AJ18*0.4 -> 0.34 | AL18: =AH18+AK18 -> 0.94 | AM18: =IF(AL18>=1,1,IF(AL18>=0.9,0.8,IF(AL18>=0.8,0.7,IF(AL18>=0.7,0.5,0)))) -> 0.8 | AN18: Dành cho kế toán
C20: III | D20: ĐÁNH GIÁ & Ý KIẾN CỦA TBP/ NGƯỜI ĐÁNH GIÁ
C21: STT | D21: Mã nhân viên | E21: Họ và tên | F21: Chức vụ | G21: Đánh giá và ý kiến trưởng bộ phận
C22: 1 | D22: E504 | E22: Hồ Hữu Thanh Sơn | F22: Leader
C23: 2 | D23: E502 | E23: Tăng Phú Vinh | F23: Staff
