Workbook

Sheet Lộ trình công danh
A1: LỘ TRÌNH CÔNG DANH - ADE 2023 -P.TK - P1
A2: Stt | B2: Kỹ năng/ Kiến thức/ Thái độ/ Kết quả/ Thời gian cống hiến | C2: NVTK | D2: Lộ trình | E2: Trưởng nhóm | F2: TP. Kỹ Thuật | G2: Gíam Đốc NM | H2: CEO | I2: Lộ trình | J2: Gíám Đốc Bộ phận | K2: CEO | L2: Tài liệu Training (Link) | M2: Người đào tạo
A3: A | B3: KỸ NĂNG
A4: I | B4: Group 1. Kỹ năng cơ bản | D4: < 2 tháng (kể từ khi nhận việc) | M4: TBP
A5: 1 | B5: Kỹ năng lập kế hoạch hàng ngày (Kế hoạch 5 phút) | C5: x | E5: x | F5: x | G5: x | H5: x | I5: Passed | J5: x | L5: To do List (Excell)
A6: 2 | B6: Kỹ năng lập kế hoạch, báo cáo tuần/ tháng/ quí/ năm | C6: x | E6: x | F6: x | G6: x | H6: x | I6: Passed | J6: x | L6: Project Follow
A7: 3 | B7: Kỹ năng làm việc theo qui trình, không có qui trình thì thực hiện theo hướng dẫn của người quản lý trực tiếp | C7: x | E7: x | F7: x | G7: x | H7: x | I7: Passed | J7: x | L7: Qui trình
A8: 4 | B8: Kỹ năng sử dụng phần mềm vào công việc được giao | C8: x | E8: x | F8: x | G8: x | H8: x | I8: Passed | J8: x | L8: Microsoft office, phần mềm báo cáo, AutoCAD) | M8: Tự học/ Trưởng nhóm
A9: 5 | B9: Kỹ năng Làm việc nhóm hoặc độc lập | C9: x | E9: x | F9: x | G9: x | H9: x | I9: Passed | J9: x | L9: A Tân cung cấp | M9: TBP
A10: 6 | B10: Kỹ năng nhận dạng và giải quyết vấn đề | C10: x | E10: x | F10: x | G10: x | H10: x | I10: Passed | J10: x | L10: A Tân cung cấp | M10: TBP
A11: 7 | B11: Tiếng anh/ đọc hiểu bản vẽ, tài liệu tiếng anh | C11: x | E11: x | F11: x | G11: x | H11: x | I11: Passed | J11: x | L11: A Tân cung cấp | M11: Tự hoc
A12: 8 | B12: Quản lý thời gian | C12: x | E12: x | F12: x | G12: x | H12: x | I12: Passed | J12: x | L12: A Tân cung cấp | M12: TBP
A13: 9 | B13: Đọc hiểu bản vẽ | C13: x | E13: x | F13: x | G13: x | H13: x | I13: Passed | J13: x | L13: Bản vẽ dự án thực tế | M13: TBP
A14: II | B14: Group 2. Kỹ năng nâng cao
A15: 1 | B15: Kỹ năng phân tích rủi ro | C15: x | D15: < 3 tháng | E15: x | F15: x | G15: x | H15: x | I15: Passed | J15: x | L15: Qui trình đã ban hành | M15: A Trọng/ TBP
A16: 2 | B16: Kỹ năng xây dựng qui trình/ hướng dẫn/ bảng cài đặt... | C16: x | D16: < 4 tháng | E16: x | F16: x | G16: x | H16: x | I16: Passed | J16: x | L16: A Hưng cung cấp | M16: A Trọng/ TBP
A17: 3 | B17: Tiếng anh/ đọc hiểu và trả lời mail, tài liệu | C17: x | D17: < 12 tháng | E17: x | F17: x | G17: x | H17: x | I17: Passed | J17: x | L17: A Tân cung cấp | M17: TBP
A18: 4 | B18: Xây dựng KPI, chính sách phúc lợi cho phòng | D18: < 5 tháng | E18: x | F18: x | G18: x | H18: x | I18: Passed | J18: x | L18: HS, xây dựng LTCD và lương 3P | M18: TBP
A19: 5 | B19: Quản lý đội nhóm & tạo động lực cho nhân viên | D19: < 6 tháng | E19: x | F19: x | G19: x | H19: x | I19: Passed | J19: x | L19: A Tân cung cấp | M19: TBP
A20: 6 | B20: Kỹ năng Đào tạo nhân viên | D20: < 7 tháng | E20: x | F20: x | G20: x | H20: x | I20: Passed | J20: x | L20: Qui trình đào tạo (theo Lộ trình đào tạo) | M20: TBP
A21: 7 | B21: Kỹ năng Điều phối cuộc họp | D21: < 8 tháng | E21: x | F21: x | G21: x | H21: x | I21: Passed | J21: x | L21: A Hưng cung cấp | M21: TBP
A22: 8 | B22: Kỹ năng giám sát đội nhóm | D22: < 9 tháng | E22: x | F22: x | G22: x | H22: x | I22: Passed | J22: x | L22: A Hưng cung cấp | M22: TBP
A23: III | B23: Group 3. Kỹ năng chuyên nghiệp
A24: 1 | B24: Kỹ năng giao tiếp & xây dựng mối quan hệ | C24: x | E24: x | F24: x | G24: x | H24: x | I24: < 1 tháng | J24: x | L24: A Tân cung cấp | M24: TBP
A25: 2 | B25: Quản lý thời gian | E25: x | F25: x | G25: x | H25: x | I25: < 1 tháng | J25: x | L25: A Tân cung cấp | M25: TBP
A26: 3 | B26: Tiếng anh/ đọc hiểu và trả lời mail, tài liệu, giao tiếp được vs người nước ngoài | E26: x | F26: x | G26: x | H26: x | I26: < 6 tháng | J26: x | L26: A Tân cung cấp | M26: TBP
A27: 4 | B27: Quản trị hệ thống & qui trình | E27: x | F27: x | G27: x | H27: x | I27: < 2 tháng | J27: x | L27: A Trọng cung cấp Index QT ISO (Update) | M27: TBP
A28: 5 | B28: Giám sát và điều hành | E28: x | F28: x | G28: x | H28: x | I28: < 2 tháng | J28: x | L28: A Tân cung cấp | M28: TBP
A29: 6 | B29: Kỹ năng giao việc và huấn luyện | E29: x | F29: x | G29: x | H29: x | I29: < 2 tháng | J29: x | L29: A Tân cung cấp | M29: TBP
A30: 7 | B30: Quản trị rủi ro | F30: x | G30: x | H30: x | I30: < 3 tháng | J30: x | L30: A Trọng cung cấp Index QT ISO (Update) | M30: TBP
A31: 8 | B31: Hoạch định chiến lược | H31: x | I31: < 3 tháng | J31: x | L31: A Tân cung cấp | M31: TBP
A32: 9 | B32: Phân tích và ra quyết định | H32: x | I32: < 4 tháng | J32: x | L32: A Tân cung cấp | M32: TBP
A33: 10 | B33: Quản trị sự thay đổi | H33: x | I33: < 4 tháng | J33: x | L33: A Tân cung cấp | M33: TBP
A34: 11 | B34: Quản trị hệ thống | H34: x | I34: < 6 tháng | J34: x | L34: A Trọng cung cấp Index QT ISO (Update) | M34: TBP
A36: B | B36: KIẾN THỨC
A37: I | B37: Kiến thức nền (Các công thức, phương pháp)
A38: 1 | B38: Công thức tính công suất hiệu dụng (P) | C38: x | D38: < 2 Tuần | E38: x | F38: x | G38: x | H38: x | I38: Passed | J38: x | L38: A Tân cung cấp | M38: A Trọng/ TBP
A39: 2 | B39: Công thức tính công suất biểu kiến (S) | C39: x | D39: < 2 Tuần | E39: x | F39: x | G39: x | H39: x | I39: Passed | J39: x | L39: A Tân cung cấp | M39: A Trọng/ TBP
A40: 3 | B40: Công thức tính dòng điện hiệu dụng (A) | C40: x | D40: < 2 Tuần | E40: x | F40: x | G40: x | H40: x | I40: Passed | J40: x | L40: A Tân cung cấp | M40: A Trọng/ TBP
A41: 4 | B41: Phương pháp tính dòng điện | C41: x | D41: < 2 Tuần | E41: x | F41: x | G41: x | H41: x | I41: Passed | J41: x | L41: A Tân cung cấp | M41: A Trọng/ TBP
...

Sheet Lo trinh công danh P.ban
A1: LỘ TRÌNH CÔNG DANH -BP THIẾT KẾ- ĐẤU THẦU
A2: Stt | B2: Kỹ năng/ Kiến thức/ Thái độ/ Kết quả/ Thời gian cống hiến | C2: Staff | D2: Senior | E2: Leader | F2: Manager | G2: Lộ trình | H2: Lộ trình | I2: Tài liệu Training (Link) | J2: Biểu mẫu áp dụng | K2: Người đào tạo | L2: Nguyễn Văn 1 Manager | M2: Nguyễn Văn 2 Leader | N2: Nguyễn Văn 3 Leader | O2: Nguyễn Văn 4 Senior | P2: Nguyễn Văn 5 staff
A3: A | B3: KỸ NĂNG
A4: I | B4: Group 1. Kỹ năng cơ bản | G4: < 2 tháng (kể từ khi nhận việc) | K4: TBP
A5: 1 | B5: Kỹ năng lập kế hoạch hàng ngày (Kế hoạch 5 phút) | C5: x | D5: x | E5: x | F5: x | H5: Passed | I5: To do List (Excell) | L5: x | M5: x | N5: x | O5: x | P5: x
A6: 2 | B6: Kỹ năng lập kế hoạch, báo cáo tuần/ tháng/ quí/ năm | C6: x | D6: x | E6: x | F6: x | H6: Passed | I6: Project Follow | L6: x | M6: x | N6: x | O6: x | P6: x
A7: 3 | B7: Kỹ năng làm việc theo qui trình, không có qui trình thì thực hiện theo hướng dẫn của người quản lý trực tiếp | C7: x | D7: x | E7: x | F7: x | H7: Passed | I7: Qui trình | L7: x | M7: x | N7: x | O7: x | P7: x
A8: 4 | B8: Kỹ năng sử dụng phần mềm vào công việc được giao | C8: x | D8: x | E8: x | F8: x | H8: Passed | I8: Microsoft office, phần mềm báo cáo, AutoCAD) | K8: Tự học/ Trưởng nhóm | L8: x | M8: x | N8: x | O8: x | P8: x
A9: 5 | B9: Kỹ năng Làm việc nhóm hoặc độc lập | C9: x | D9: x | E9: x | F9: x | H9: Passed | I9: A Tân cung cấp | K9: TBP | L9: x | M9: x | N9: x | O9: x | P9: x
A10: 6 | B10: Kỹ năng nhận dạng và giải quyết vấn đề | C10: x | D10: x | E10: x | F10: x | H10: Passed | I10: A Tân cung cấp | K10: TBP | L10: x | M10: x | N10: x | O10: x | P10: x
A11: 7 | B11: Tiếng anh/ đọc hiểu bản vẽ, tài liệu tiếng anh | C11: x | D11: x | E11: x | F11: x | H11: Passed | I11: A Tân cung cấp | K11: Tự hoc | L11: x | M11: x | N11: x | O11: x | P11: x
A12: 8 | B12: Quản lý thời gian | C12: x | D12: x | E12: x | F12: x | H12: Passed | I12: A Tân cung cấp | K12: TBP | L12: x | M12: x | N12: x | O12: x | P12: x
A13: 9 | B13: Đọc hiểu bản vẽ | C13: x | D13: x | E13: x | F13: x | H13: Passed | I13: Bản vẽ dự án thực tế | K13: TBP | L13: x | M13: x | N13: x | O13: x | P13: x
A14: II | B14: Group 2. Kỹ năng nâng cao
A15: 1 | B15: Kỹ năng phân tích rủi ro thi công | E15: x | F15: x | G15: < 3 tháng | H15: Passed | I15: Qui trình đã ban hành | K15: A Trọng/ TBP | L15: x | M15: x | N15: x | O15: x
A16: 2 | B16: Kỹ năng xây dựng qui trình | E16: x | F16: x | G16: < 4 tháng | H16: Passed | I16: A Hưng cung cấp | K16: A Trọng/ TBP | L16: x | M16: x | N16: x
A17: 3 | B17: Xây dựng KPI, chính sách phúc lợi cho phòng | F17: x | G17: < 5 tháng | H17: Passed | I17: HS, xây dựng LTCD và lương 3P | K17: TBP | L17: x
A18: 4 | B18: Quản lý đội nhóm & tạo động lực cho nhân viên | E18: x | F18: x | G18: < 6 tháng | H18: Passed | I18: A Tân cung cấp | K18: TBP | L18: x | M18: x | N18: x
A19: 5 | B19: Kỹ năng Đào tạo nhân viên | E19: x | F19: x | G19: < 7 tháng | H19: Passed | I19: Qui trình đào tạo (theo Lộ trình đào tạo) | K19: TBP | L19: x | M19: x | N19: x
A20: 6 | B20: Kỹ năng Điều phối cuộc họp | E20: x | F20: x | G20: < 8 tháng | H20: Passed | I20: A Hưng cung cấp | K20: TBP | L20: x | M20: x | N20: x
A21: 7 | B21: Kỹ năng giám sát đội nhóm | E21: x | F21: x | G21: < 9 tháng | H21: Passed | I21: A Hưng cung cấp | K21: TBP | L21: x | M21: x | N21: x
A22: 8 | B22: Tiếng anh/ đọc hiểu và trả lời mail, tài liệu, giao tiếp được | D22: x | E22: x | F22: x | G22: < 12 tháng | H22: Passed | I22: A Tân cung cấp | K22: TBP | L22: x | M22: x | N22: x | O22: x
A23: III | B23: Group 3. Kỹ năng chuyên nghiệp
A24: 1 | B24: Kỹ năng giao tiếp & xây dựng mối quan hệ | C24: x | D24: x | E24: x | F24: x | H24: < 1 tháng | I24: A Tân cung cấp | K24: TBP | L24: x | M24: x | N24: x | O24: x
A25: 2 | B25: Quản lý thời gian | C25: x | D25: x | E25: x | F25: x | H25: < 1 tháng | I25: A Tân cung cấp | K25: TBP | L25: x | M25: x | N25: x | O25: x
A26: 3 | B26: Tiếng anh/ đọc hiểu và trả lời mail, tài liệu, giao tiếp được vs người nước ngoài | D26: x | E26: x | F26: x | H26: < 6 tháng | I26: A Tân cung cấp | K26: TBP | L26: x | M26: x | N26: x | O26: x
A27: 4 | B27: Quản trị hệ thống & qui trình | E27: x | F27: x | H27: < 2 tháng | I27: A Trọng cung cấp Index QT ISO (Update) | K27: TBP | L27: x | M27: x | N27: x
A28: 5 | B28: Giám sát và điều hành | E28: x | F28: x | H28: < 2 tháng | I28: A Tân cung cấp | K28: TBP | L28: x | M28: x | N28: x
A29: 6 | B29: Kỹ năng giao việc và huấn luyện | E29: x | F29: x | H29: < 2 tháng | I29: A Tân cung cấp | K29: TBP | L29: x | M29: x | N29: x
A30: 7 | B30: Lập kế hoạch, xây dựng chiến lược triển khai quản lý dự án | F30: x | H30: < 3 tháng | I30: A Tân cung cấp | K30: TBP | L30: x
A31: 8 | B31: Quản trị rủi ro | F31: x | H31: < 3 tháng | I31: A Trọng cung cấp Index QT ISO (Update) | K31: TBP | L31: x
A32: 9 | B32: Hoạch định chiến lược | F32: x | H32: < 3 tháng | I32: A Tân cung cấp | K32: TBP | L32: x
A33: 10 | B33: Phân tích và ra quyết định | F33: x | H33: < 4 tháng | I33: A Tân cung cấp | K33: TBP | L33: x
A34: 11 | B34: Quản trị sự thay đổi | F34: x | H34: < 4 tháng | I34: A Tân cung cấp | K34: TBP | L34: x
A35: 12 | B35: Quản trị hệ thống | F35: x | H35: < 6 tháng | I35: A Trọng cung cấp Index QT ISO (Update) | K35: TBP | L35: x
A36: B | B36: KIẾN THỨC
A37: I | B37: Kiến thức nền (Các công thức, phương pháp)
A38: 1 | B38: Công thức tính công suất hiệu dụng (P) | C38: x | D38: x | E38: x | F38: x | G38: < 2 Tuần | H38: Passed | I38: A Tân cung cấp | K38: A Trọng/ TBP | L38: x | M38: x | N38: x | O38: x | P38: x
A39: 2 | B39: Công thức tính công suất biểu kiến (S) | C39: x | D39: x | E39: x | F39: x | G39: < 2 Tuần | H39: Passed | I39: A Tân cung cấp | K39: A Trọng/ TBP | L39: x | M39: x | N39: x | O39: x | P39: x
A40: 3 | B40: Công thức tính dòng điện hiệu dụng (A) | C40: x | D40: x | E40: x | F40: x | G40: < 2 Tuần | H40: Passed | I40: A Tân cung cấp | K40: A Trọng/ TBP | L40: x | M40: x | N40: x | O40: x | P40: x
...

Sheet P2.1 (Kiến thức)
A1: CÔNG TY TNHH KỸ THUẬT TỰ ĐỘNG AN DƯƠNG
A2: ĐÁNH GIÁ NHÂN VIÊN THIẾT KẾ - ĐẤU THẦU
B3: Ngày: 30/04/2026
B4: Mục đích kiểm tra/ đánh giá:
A5: ĐIỂM CHUẨN CẦN PHẢI ĐÁP ỨNG HƯỞNG LƯƠNG THEO VỊ TRÍ - P2.1
A6: Stt | B6: Kỹ năng/ Kiến thức/ Thái độ/ Kết quả/ Thời gian làm việc | C6: Thang điểm Cộng/ trừ (Tham khảo) | D6: Thang điểm 100 | E6: Diễn giải | F6: Nguyễn Hoàng Minh Nhựt
A7: A (TC1) | B7: KỸ NĂNG | D7: =D8+D18+D27 -> 35 | E7: KỸ NĂNG | F7: =F8+F18+F27 -> 30
A8: I | B8: Group 1. Kỹ năng cơ bản | D8: 15 | E8: Group 1. Kỹ năng cơ bản | F8: 14
A9: 1 | B9: Không có kế hoạch hàng ngày (Kế hoạch 5 phút) | C9: -1 | E9: Kỹ năng lập kế hoạch hàng ngày (Kế hoạch 5 phút)
A10: 2 | B10: Không có kế hoạch, báo cáo tuần/ tháng/ quí/ năm | C10: -2 | E10: Kỹ năng lập kế hoạch, báo cáo tuần/ tháng/ quí/ năm
A11: 3 | B11: Không làm việc theo qui trình, không thực hiện theo hướng dẫn của người quản lý trực tiếp | C11: -2 | E11: Kỹ năng làm việc theo qui trình, không có qui trình thì thực hiện theo hướng dẫn của người quản lý trực tiếp
A12: 4 | B12: Không sử dụng phần mềm vào công việc được giao | C12: -1 | E12: Kỹ năng sử dụng phần mềm vào công việc được giao
A13: 5 | B13: Không hợp tác Làm việc nhóm | C13: -2 | E13: Kỹ năng Làm việc nhóm hoặc độc lập
A14: 6 | B14: Không chủ động nhận dạng và giải quyết vấn đề | C14: -2 | E14: Kỹ năng nhận dạng và giải quyết vấn đề | F14: -1
A15: 7 | B15: Không đọc được tiếng anh/ đọc hiểu bản vẽ, tài liệu tiếng anh | C15: -1 | E15: Tiếng anh/ đọc hiểu bản vẽ, tài liệu tiếng anh
A16: 8 | B16: Không biết Quản lý thời gian & sắp xếp công việc phù hợp | C16: -2 | E16: Quản lý thời gian
A17: 9 | B17: Không hiểu bản vẽ, không kiểm tra bản vẽ trước khi gửi đi | C17: -2 | E17: Đọc hiểu bản vẽ/ kiểm tra bản vẽ trước khi gửi đi
A18: II | B18: Group 2. Kỹ năng nâng cao | D18: 10 | E18: Group 2. Kỹ năng nâng cao | F18: 8
A19: 1 | B19: Không thực hiện phân tích rủi ro | C19: -2 | E19: Kỹ năng phân tích rủi ro thi công
A20: 2 | B20: Không biết viết qui trình/ hướng dẫn/ bảng cài đặt... | C20: -2 | E20: Kỹ năng xây dựng qui trình
A21: 3 | B21: Không Xây dựng KPI, chính sách phúc lợi cho phòng | C21: -1 | E21: Xây dựng KPI, chính sách phúc lợi cho phòng
A22: 4 | B22: Không Quản lý đội nhóm & tạo động lực cho nhân viên | C22: -1 | E22: Quản lý đội nhóm & tạo động lực cho nhân viên
A23: 5 | B23: Không Kỹ năng Đào tạo nhân viên | C23: -1 | E23: Kỹ năng Đào tạo nhân viên
A24: 6 | B24: Kỹ năng Điều phối cuộc họp | C24: -1 | E24: Kỹ năng Điều phối cuộc họp
A25: 7 | B25: Kỹ năng giám sát đội nhóm không tốt | C25: -1 | E25: Kỹ năng giám sát đội nhóm
A26: 8 | B26: Không có kiến thức về Tiếng anh/ đọc hiểu và trả lời mail, tài liệu, giao tiếp được | C26: -1 | E26: Tiếng anh/ đọc hiểu và trả lời mail, tài liệu, giao tiếp được
A27: III | B27: Group 3. Kỹ năng chuyên nghiệp | D27: 10 | E27: Group 3. Kỹ năng chuyên nghiệp | F27: 8
A28: 1 | B28: Kỹ năng giao tiếp & xây dựng mối quan hệ | C28: -1 | E28: Kỹ năng giao tiếp & xây dựng mối quan hệ
A29: 2 | B29: Quản lý thời gian | C29: -2 | E29: Quản lý thời gian
A30: 3 | B30: Tiếng anh/ đọc hiểu và trả lời mail, tài liệu, giao tiếp được vs người nước ngoài | C30: -1 | E30: Tiếng anh/ đọc hiểu và trả lời mail, tài liệu, giao tiếp được vs người nước ngoài
A31: 4 | B31: Quản trị hệ thống & qui trình | C31: -2 | E31: Quản trị hệ thống & qui trình
A32: 5 | B32: Giám sát và điều hành | C32: -1 | E32: Giám sát và điều hành
A33: 6 | B33: Kỹ năng giao việc và huấn luyện | C33: -1 | E33: Kỹ năng giao việc và huấn luyện
A34: 7 | B34: Lập kế hoạch, xây dựng chiến lược triển khai quản lý dự án | C34: -1 | E34: Lập kế hoạch, xây dựng chiến lược triển khai quản lý dự án
A35: 8 | B35: Quản trị rủi ro | C35: -1 | E35: Quản trị rủi ro
A36: 9 | B36: Hoạch định chiến lược | C36: +1 | E36: Hoạch định chiến lược
A37: 10 | B37: Phân tích và ra quyết định | C37: +1 | E37: Phân tích và ra quyết định
A38: 11 | B38: Quản trị sự thay đổi | C38: +1 | E38: Quản trị sự thay đổi
A39: 12 | B39: Quản trị hệ thống | C39: +1 | E39: Quản trị hệ thống
A40: B (TC2) | B40: KIẾN THỨC | D40: =D41+D57+D99+D109 -> 40 | E40: KIẾN THỨC | F40: =F41+F57+F99+F109 -> 24
...

Sheet P2.2 (Kỹ năng chuyên môn)
D2: BẢNG TỔNG HỢP ĐÁNH GIÁ THỰC HIỆN CÔNG VIỆC CÔNG NHÂN VIÊN | T2: Mã số
T3: Lần ban hành
T4: Lần sửa đổi
H6: PHÒNG: THIẾT KẾ - ĐẤU THẦU
I7: Tháng: T04-2026
B9: STT | C9: HỌ VÀ TÊN | D9: CHỨC VỤ | E9: CHỈ TIÊU ĐÁNH GIÁ | U9: TỔNG ĐIỂM | V9: XẾP LOẠI | W9: GHI CHÚ
E10: 1 | F10: 2 | G10: 3 | H10: 4 | I10: 5 | J10: 6 | K10: 7 | L10: 8 | M10: 9 | N10: 10 | O10: 11 | P10: 12 | Q10: 13 | R10: 14 | S10: 15 | T10: 16
E11: Tay nghề & Kỹ năng thực hiện công việc | F11: Chất lượng thực hiện công việc (tuân thủ các mục tiêu chuẩn & quy trình) | G11: Khối lượng & tiến độ công việc hoàn thành | H11: Làm việc nhóm & Hợp tác thực hiện công việc | I11: Ý thức đảm bảo an toàn lao động | J11: Ý thức bảo vệ tài sản của công ty & CĐT tại công trường | K11: Ý thức sử dụng tiết kiệm tài sản của Công ty (điện, nước, vật tư, thiết bị lắp đặt…) | L11: Thái độ, ý thức trách nhiệm đối với công việc | M11: Quan hệ với đồng nghiệp & những người khác trên công trường | N11: Kỷ luật trong CV, ý thức chấp hành nội quy công ty | O11: Mặc đồng phục, đeo thẻ đầy đủ & đúng quy định | P11: Ý thức sử dụng thời gian làm việc | Q11: Ý thức chấp hành lệnh phân công, điều hành của quản trị viên, BGĐ | R11: Giữ gìn vệ sinh | S11: Đi làm đầy đủ | T11: Đi làm đúng giờ
E12: 8 | F12: 8 | G12: 8 | H12: 8 | I12: 8 | J12: 6 | K12: 8 | L12: 6 | M12: 6 | N12: 6 | O12: 6 | P12: 6 | Q12: 6 | R12: 4 | S12: 4 | T12: 4 | U12: 100
B13: 1 | C13: Nguyễn Hoàng Minh Nhựt | D13: NV Thiết kế | E13: 5 | F13: 5 | G13: 6 | H13: 6 | I13: 6 | J13: 6 | K13: 6 | L13: 5 | M13: 5 | N13: 6 | O13: 6 | P13: 5 | Q13: 5 | R13: 4 | S13: 0 | T13: 2 | U13: =SUM(E13:T13) -> 78
D14: Chỉ huy công trình đánh giá
C15: Nguyễn Tiến Thành | D15: QTV đánh giá | E15: 5 | F15: 5 | G15: 6 | H15: 6 | I15: 6 | J15: 5 | K15: 5 | L15: 5 | M15: 5 | N15: 6 | O15: 5 | P15: 5 | Q15: 5 | R15: 4 | S15: 0 | T15: 2 | U15: =SUM(E15:T15) -> 75
P18: Ngày 30 tháng 04 năm 2026
D19: Trưởng Phòng | P19: Giám đốc chuyên trách
D20: (Hoặc Trưởng Bộ phận
D21: Bảo trì, Phó trưởng VPĐD)
D25: Nguyễn Tiến Thành

Sheet P3.1.1 (KPI ca nhan-Senior)
C1: QUẢN TRỊ HIỆU SUẤT | D1: CÔNG TY TNHH KỸ THUẬT TỰ ĐỘNG AN DƯƠNG BẢNG KPI : PHÒNG THIẾT KẾ - ĐÁU THẦU THÁNG 04 NĂM 2026
C3: Căn cứ quy định đánh giá hiệu quả công việc hiện hành
C4: Căn cứ kế hoạch phát triển công ty | I4: Người đánh giá : Nguyễn Tiến Thành
A6: STT | B6: Khía cạnh ADE | C6: Yếu tố quyết định thành công | D6: Chỉ tiêu đánh giá (KPI) | E6: Stt KPI | F6: Đơn vị đo lường | G6: Trọng số (%) (số điểm KPI bị trừ khi quy phạm 1 trong những tiêu chí) | H6: Mục tiêu 2026 | I6: Kém | J6: Xuất sắc | K6: Diễn giải | L6: Điểm Đánh Giá KPI Nguyễn Hoàng Minh Nhựt
L8: Số lần vi phạm | M8: Điểm thưởng bị trừ
G9: =SUM(G10:G27) -> 1 | L9: 1 | M9: =SUM(M10:M27) -> 0.35
A10: TC1 | B10: An Toàn | C10: Trang bị đầy đủ trang thiết bị an toàn đúng, đủ với tính chất công việc thực hiện | D10: Trang bị bảo hộ lao động đầy đủ cho nhân viên, công nhân thi công | E10: PTK-KPI 1 | F10: Số lần vi phạm / tháng (kiểm tra 2 lần/ ngày) | G10: 0.1 | H10: 0 Lần / Tháng | I10: 1 Lần/Tháng | J10: 0 Lần / Tháng | K10: Điểm thưởng KPI sẽ bị trừ nếu vi phạm một trong những tiêu chí này | L10: 0 | M10: =IF(SUM(L10:L13)>=1,$G$10,0) -> 0
C11: Thiết bị thi công cụ dụng cụ đảm bảo tiêu chuẩn | D11: Nội quy công trường: an toàn, cấm hút thuốc.v.v… Nơi làm việc đảm bảo an toàn | F11: Số lần kiểm tra 2 lần/ ngày | H11: 0 Lần / Tháng | I11: 1 Lần/Tháng | J11: 0 Lần / Tháng | L11: 0
D12: Thiết bị, công cụ dụng cụ thi công có kiểm định, kiểm tra định kỳ.Dàn giáo, dây đai, thang, máy cắt, khoan, máy hàn, xe cẩu, xe nâng… có kiểm định/ chứng nhận an toàn, kiểm tra định kỳ và còn hiệu lực | F12: Số lần vi phạm / tháng (kiểm tra 1 lần/ tháng) | H12: 0 Lần / Tháng | I12: 1 Lần/Tháng | J12: 0 Lần / Tháng | L12: 0
C13: Phân tích, đánh giá rủi ro, phương pháp làm việc an toàn khi thực hiện | D13: Lập bảng phân tích, đánh giá rủi ro, biện pháp phòng ngừa | F13: Số lần vi phạm / hạn mục (kiểm tra bất kỳ thời gian DA) | H13: 0 Lần / Tháng | I13: 1 Lần/Tháng | J13: 0 Lần / Tháng | L13: 0
A14: TC2 | B14: Kỹ thuật/ Chất lượng | C14: Sự hài lòng của khách hàng Sản phẩm đạt chất lượng kỹ thuật | D14: Thiết kế đúng kỹ thuật ( Tiêu chuẩn IEC / TCVN ) | E14: PTK-KPI 2 | F14: Số lỗi thiết kế/1 dự án, việc | G14: 0.2 | H14: 0 Lỗi / DA/ Việc | I14: 1 Lỗi / DA/việc | J14: 0 Lỗi / DA/việc | K14: Điểm thưởng KPI sẽ bị trừ nếu vi phạm một trong những tiêu chí này | L14: 0 | M14: =IF(SUM(L14:L16)>=1,$G$14,0) -> 0
D15: Cung cấp đầy đủ hồ sơ thiết kế ( Bản vẽ, BOM, Spec, ..) | F15: Số lần thiếu hồ sơ/1 dự án, việc | H15: 0 Lỗi / DA/ Việc | I15: 1 Lỗi / DA/việc | J15: 0 Lỗi / DA/việc | L15: 0
D16: Chọn lựa thiết bị đúng ( Tiêu chuẩn IEC / TCVN ) | F16: Số lần chọn sai thiết bị/1 dự án, việc | H16: 0 Lỗi / DA/ Việc | I16: 1 Lỗi / DA/việc | J16: 0 Lỗi / DA/việc | L16: 0
A17: TC3 | B17: Qui trình | C17: Quy trình và quản lý An toàn, chất lượng, Kỹ thuật | D17: Áp dụng qui trình cho từng công đoạn của công việc | E17: PTK-KPI 3 | F17: Số lần không áp dụng qui trình/ tháng | G17: 0.15 | H17: 0 | I17: 1 | J17: 0 | K17: Điểm thưởng KPI sẽ bị trừ nếu vi phạm một trong những tiêu chí này | L17: 0 | M17: =IF(SUM(L17:L20)>=1,$G$17,0) -> 0
C18: Hiệu suất | D18: Đề xuất phương án thực hiện | F18: Phương án/ giải pháp thực hiện công việc | H18: 3 phương án | I18: 1 | J18: 3 phương án, có 1 phuong án tối ưu/ 1 sự việc | L18: 0
D19: Cải tiến sản phẩm, Kaizen | F19: Số lần /tháng | H19: 1 Lần | I19: 0 Lần | J19: > 2 Lần | L19: 0
D20: Qui trình 5S | F20: Số lần vi phạm/ ko thực hiện/tháng | H20: 0 | I20: 1 Lần | J20: 0 | L20: 0
A21: TC4 | B21: Tiến độ | C21: Tiến độ thực hiện công việc | D21: Thực hiện công việc kịp tiến độ | E21: PTK-KPI 4 | F21: Số lần trễ tiến độ /dự án | G21: 0.2 | H21: 0 Lần | I21: 1 lần | J21: 0 Lần | K21: Điểm thưởng KPI sẽ bị trừ nếu vi phạm một trong những tiêu chí này | L21: 1 | M21: =IF(SUM(L21:L22)>=1,$G$21,0) -> 0.2
D22: Báo cáo đúng hạn, đầy đủ thông tin | F22: Số lần báo cáo không kịp thời, không đạt yêu cầu/tháng | H22: 0 Lần | I22: 1 lần | J22: 0 Lần | L22: 0
A23: TC5 | B23: Chi Phí | C23: Giảm chi phí tối thiểu | D23: Giảm thất thoát vật tư trong lập dự toán | E23: PTK-KPI 5 | F23: Giới hạn PS chi phí +/- 2% | G23: 0.15 | H23: 0.01 | I23: <2%, >2% | J23: </= 1% | K23: Điểm thưởng KPI sẽ bị trừ nếu vi phạm một trong những tiêu chí này | L23: 0 | M23: =IF(SUM(L23:L24)>=1,$G$23,0) -> 0
D24: Khảo sát, đo đạc, thiết kế bản vẽ theo thực tế thi công dự án 100% | F24: Sai lệch so với thực tế thi công +/- 2% | H24: 0.01 | I24: <2%, >2% | J24: </= 1% | L24: 0
A25: TC6 | B25: Đào tạo và Phẫm chất | C25: Đào tạo nhân viên theo kế hoạch đào tạo | D25: Chất lượng nhân sự đáp ứng nhu cầu | E25: PTK-KPI 6 | F25: % nhân sự đạt yêu cầu /tổng số nhân viên phòng ban | G25: 0.15 | H25: >80% | I25: <80% | J25: 100 | K25: Điểm thưởng KPI sẽ bị trừ nếu vi phạm một trong những tiêu chí này | L25: 0 | M25: =IF(SUM(L25:L26)>=1,$G$25,0) -> 0.15
C26: Nội quy công ty | D26: Nội quy công ty, nội quy công trình | F26: Số lần vi phạm /tháng | H26: 0 lần / tháng | I26: 2lần / tháng | J26: 0 lần / tháng | L26: 1
A27: TC7 | B27: Thẩm Mỹ | C27: Tiêu chí đạt thẩm mỹ | D27: 2 /3 ý kiến đánh giá đạt trong đó có 1 ý kiến khách hàng ( Cấp giám đốc nhà máy trở lên ) | E27: PTK-KPI 7 | F27: 2 /3 ý kiến đánh giá đạt trong đó có 1 ý kiến khách hàng ( Cấp giám đốc nhà máy trở lên ) | G27: 0.05 | H27: >80% | I27: <80% | J27: 90% | K27: Điểm thưởng KPI sẽ bị trừ nếu vi phạm một trong những tiêu chí này | L27: 0 | M27: =IF(SUM(L27:L27)>=1,$G$27,0) -> 0

Sheet P3.1.1 (KPI Phong Ban)
C1: QUẢN TRỊ HIỆU SUẤT | D1: CÔNG TY TNHH KỸ THUẬT TỰ ĐỘNG AN DƯƠNG BẢNG KPI : PHÒNG THIẾT KẾ - ĐẤU THẦU THÁNG 04 NĂM 2026
C3: Căn cứ quy định đánh giá hiệu quả công việc hiện hành
C4: Căn cứ kế hoạch phát triển công ty | I4: Người đánh giá : Nguyễn Phước Tân
A6: STT | B6: Khía cạnh ADE | C6: Yếu tố quyết định thành công | D6: Chỉ tiêu đánh giá (KPI) | E6: Stt KPI | F6: Đơn vị đo lường | G6: Trọng số (%) (số điểm KPI bị trừ khi quy phạm 1 trong những tiêu chí) | H6: Mục tiêu 2026 | I6: Kém | J6: Xuất sắc | K6: Diễn giải | L6: Điểm Đánh Giá KPI Phòng Ban
L7: Số lần vi phạm | M7: Điểm thưởng bị trừ
G8: =SUM(G9:G28) -> 1 | L8: =SUM(L9:L28) -> 8 | M8: =SUM(M9:M28) -> 0.9
A9: TC1 | B9: An Toàn | C9: Trang bị đầy đủ trang thiết bị an toàn đúng, đủ với tính chất công việc thực hiện | D9: Trang bị bảo hộ lao động đầy đủ cho nhân viên, công nhân thi công | E9: PTK-KPI 1 | F9: Số lần vi phạm / tháng (kiểm tra 2 lần/ ngày) | G9: 0.1 | H9: 0 Lần / Tháng | I9: 1 Lần/Tháng | J9: 0 Lần / Tháng | K9: Điểm thưởng KPI sẽ bị trừ nếu vi phạm một trong những tiêu chí này | L9: 0 | M9: =IF(SUM(L9:L13)>=1,$G$9,0) -> 0
C10: Thiết bị thi công cụ dụng cụ đảm bảo tiêu chuẩn | D10: Nội quy công trường: an toàn, cấm hút thuốc.v.v… Nơi làm việc đảm bảo an toàn | F10: Số lần kiểm tra 2 lần/ ngày | H10: 0 Lần / Tháng | I10: 1 Lần/Tháng | J10: 0 Lần / Tháng | L10: 0
D11: Thiết bị, công cụ dụng cụ thi công có kiểm định, kiểm tra định kỳ.Dàn giáo, dây đai, thang, máy cắt, khoan, máy hàn, xe cẩu, xe nâng… có kiểm định/ chứng nhận an toàn, kiểm tra định kỳ và còn hiệu lực | F11: Số lần vi phạm / tháng (kiểm tra 1 lần/ tháng) | H11: 0 Lần / Tháng | I11: 1 Lần/Tháng | J11: 0 Lần / Tháng | L11: 0
C12: Phân tích, đánh giá rủi ro, phương pháp làm việc an toàn khi thực hiện | D12: Lập bảng phân tích, đánh giá rủi ro, biện pháp phòng ngừa | F12: Số lần vi phạm / hạn mục (kiểm tra bất kỳ thời gian DA) | H12: 0 Lần / Tháng | I12: 1 Lần/Tháng | J12: 0 Lần / Tháng | L12: 0
C13: Đào tạo, huấn luyện an toàn CBNV | D13: Họp nhắc nhỡ, huấn luyện hàng ngày, trước khi làm việc Đào tạo định kỳ, đào tạo cho NV mới | F13: Số lần tai nạn trong tháng | H13: 0 Lần / Tháng | I13: 1 Lần/Tháng | J13: 0 Lần / Tháng | L13: 0
A14: TC2 | B14: Kỹ thuật/ Chất lượng | C14: Sự hài lòng của khách hàng Sản phẩm đạt chất lượng kỹ thuật | D14: Thiết kế đúng kỹ thuật ( Tiêu chuẩn IEC / TCVN ) | E14: PTK-KPI 2 | F14: Số lỗi thiết kế/1 dự án, việc | G14: 0.2 | H14: 0 Lỗi / DA/ Việc | I14: 1 Lỗi / DA/việc | J14: 0 Lỗi / DA/việc | K14: Điểm thưởng KPI sẽ bị trừ nếu vi phạm một trong những tiêu chí này | L14: 1 | M14: =IF(SUM(L14:L16)>=1,$G$14,0) -> 0.2
D15: Cung cấp đầy đủ hồ sơ thiết kế ( Bản vẽ, BOM, Spec, ..) | F15: Số lần thiếu hồ sơ/1 dự án, việc | H15: 0 Lỗi / DA/ Việc | I15: 1 Lỗi / DA/việc | J15: 0 Lỗi / DA/việc | L15: 1
D16: Chọn lựa thiết bị đúng ( Tiêu chuẩn IEC / TCVN ) | F16: Số lần chọn sai thiết bị/1 dự án, việc | H16: 0 Lỗi / DA/ Việc | I16: 1 Lỗi / DA/việc | J16: 0 Lỗi / DA/việc | L16: 0
A17: TC3 | B17: Qui trình | C17: Quy trình và quản lý An toàn, chất lượng, Kỹ thuật | D17: Áp dụng qui trình cho từng công đoạn của công việc | E17: PTK-KPI 3 | F17: Số lần không áp dụng qui trình/ tháng | G17: 0.15 | H17: 0 | I17: 1 | J17: 0 | K17: Điểm thưởng KPI sẽ bị trừ nếu vi phạm một trong những tiêu chí này | L17: 0 | M17: =IF(SUM(L17:L20)>=1,$G$17,0) -> 0.15
C18: Hiệu suất | D18: Đề xuất phương án thực hiện | F18: Phương án/ giải pháp thực hiện công việc | H18: 3 phương án | I18: 1 | J18: 3 phương án, có 1 phuong án tối ưu/ 1 sự việc
D19: Cải tiến sản phẩm, Kaizen | F19: Số lần /tháng | H19: 1 Lần | I19: 0 Lần | J19: > 2 Lần | L19: 1
D20: Qui trình 5S | F20: Số lần vi phạm/ ko thực hiện/tháng | H20: 0 | I20: 1 Lần | J20: 0 | L20: 0
A21: TC4 | B21: Tiến độ | C21: Tiến độ thực hiện công việc | D21: Thực hiện công việc kịp tiến độ | E21: PTK-KPI 4 | F21: Số lần trễ tiến độ /dự án | G21: 0.2 | H21: 0 Lần | I21: 1 lần | J21: 0 Lần | K21: Điểm thưởng KPI sẽ bị trừ nếu vi phạm một trong những tiêu chí này | L21: 1 | M21: =IF(SUM(L21:L22)>=1,$G$21,0) -> 0.2
D22: Báo cáo đúng hạn, đầy đủ thông tin | F22: Số lần báo cáo không kịp thời, không đạt yêu cầu/tháng | H22: 0 Lần | I22: 1 lần | J22: 0 Lần | L22: 0
A23: TC5 | B23: Chi Phí | C23: Giảm chi phí tối thiểu | D23: Giảm thất thoát vật tư trong lập dự toán | E23: PTK-KPI 5 | F23: Giới hạn PS chi phí +/- 2% | G23: 0.15 | H23: 0.01 | I23: <2%, >2% | J23: </= 1% | K23: Điểm thưởng KPI sẽ bị trừ nếu vi phạm một trong những tiêu chí này | L23: 1 | M23: =IF(SUM(L23:L24)>=1,$G$23,0) -> 0.15
D24: Khảo sát, đo đạc, thiết kế bản vẽ theo thực tế thi công dự án 100% | F24: Sai lệch so với thực tế thi công +/- 2% | H24: 0.01 | I24: <2%, >2% | J24: </= 1% | L24: 0
A25: TC6 | B25: Đào tạo và Phẫm chất | C25: Đào tạo nhân viên theo kế hoạch đào tạo | D25: Đào tạo /người | E25: PTK-KPI 6 | F25: % số khóa đào tạo thực hiện/kế hoạch | G25: 0.15 | H25: >80% | I25: <80% | J25: 100 | K25: Điểm thưởng KPI sẽ bị trừ nếu vi phạm một trong những tiêu chí này | L25: 1 | M25: =IF(SUM(L25:L27)>=1,$G$25,0) -> 0.15
D26: Chất lượng nhân sự đáp ứng nhu cầu | F26: % nhân sự đạt yêu cầu /tổng số nhân viên phòng ban | H26: >80% | I26: <80% | J26: 100 | L26: 1
C27: Nội quy công ty | D27: Nội quy công ty, nội quy công trình | F27: Số lần vi phạm /tháng | H27: 0 lần / tháng | I27: 2lần / tháng | J27: 0 lần / tháng | L27: 0
A28: TC7 | B28: Thẩm Mỹ | C28: Tiêu chí đạt thẩm mỹ | D28: 2 /3 ý kiến đánh giá đạt trong đó có 1 ý kiến khách hàng ( Cấp giám đốc nhà máy trở lên ) | E28: PTK-KPI 7 | F28: 2 /3 ý kiến đánh giá đạt trong đó có 1 ý kiến khách hàng ( Cấp giám đốc nhà máy trở lên ) | G28: 0.05 | H28: >80% | I28: <80% | J28: 90% | K28: Điểm thưởng KPI sẽ bị trừ nếu vi phạm một trong những tiêu chí này | L28: 1 | M28: =IF(SUM(L28:L28)>=1,$G$28,0) -> 0.05

Sheet Kết Quả Đánh Giá 3P
D2: BẢNG ĐÁNH GIÁ THEO PHƯƠNG PHÁP 3P | AO2: No. AUT. Date: 30/4/2026 Page: 01/01
C6: I | D6: THÔNG TIN CHUNG
D7: Bộ phận được đánh giá: | E7: THIẾT KẾ - ĐẤU THẦU
D8: Tháng đánh giá: | E8: T04/2026
D9: Người đánh giá: | E9: Nguyễn Tiến Thành
D10: Tiêu chí đánh giá | E10: Phương pháp 3P với trọng số
D12: Chú ý: đây là bảng tổng hợp Lương 3P của nhân viên phòng ban. Cuối mỗi tháng, trưởng bộ phận sẽ đánh giá nhân viên các tiêu chí P2.1; P2.2; P3.1.1; P3.1.2 tại các sheet tương ứng
C13: II | D13: BẢNG TỔNG HỢP KẾT QUẢ
C14: STT | D14: Mã nhân viên | E14: Họ và tên | F14: Chức vụ | G14: TIÊU CHÍ P1 (lương theo vị trí) | I14: TIÊU CHÍ P2 (lương theo năng lực) | AF14: TIÊU CHÍ P3 (lương theo hiệu quả công việc)
G15: P1.1 (lương cơ bản) | H15: P1.2 (lương chuyên môn, chức vụ) Đánh giá theo định kỳ | I15: P2.1 (lương theo kiến thức công việc) Đánh giá theo định kỳ | O15: P2.2 (lương theo kỹ năng, kinh nghiệm) Đánh giá theo định kỳ | AF15: P3.1 | AN15: P3.2 (theo doanh thu)
AF16: P3.1.1 KPI CÁ NHÂN (1) | AI16: P3.1.2 KPI PHÒNG BAN (2) | AL16: KPI NHÂN VIÊN = (1) X (2) | AO16: Ghi chú
G17: Mức lương | H17: Mức lương | I17: TC1 | J17: TC2 | K17: TC3 | L17: TC4 | M17: TC5 | N17: Hệ Số | O17: TC1 | P17: TC2 | Q17: TC3 | R17: TC4 | S17: TC5 | T17: TC6 | U17: TC7 | V17: TC8 | W17: TC9 | X17: TC10 | Y17: TC11 | Z17: TC12 | AA17: TC13 | AB17: TC14 | AC17: TC15 | AD17: TC16 | AE17: Hệ Số | AF17: Điểm thưởng bị trừ | AG17: Điểm | AH17: Trọng số | AI17: Điểm thưởng bị trừ | AJ17: Điểm | AK17: Trọng số | AL17: Tổng trọng số | AM17: Hệ số | AN17: Hệ số
C18: 1 | D18: E706 | E18: ='P2.1 (Kiến thức)'!F6 -> Nguyễn Hoàng Minh Nhựt | F18: Senior | G18: Dành cho kế toán | H18: Dành cho kế toán | I18: ='P2.1 (Kiến thức)'!F7 -> 30 | J18: ='P2.1 (Kiến thức)'!F40 -> 24 | K18: ='P2.1 (Kiến thức)'!F123 -> 15 | L18: ='P2.1 (Kiến thức)'!F139 -> 3 | M18: 3 | N18: =SUM(I18:M18)/100 -> 0.75 | O18: 5 | P18: 5 | Q18: 6 | R18: 6 | S18: 6 | T18: 5 | U18: 5 | V18: 5 | W18: 5 | X18: 6 | Y18: 5 | Z18: 5 | AA18: 5 | AB18: 4 | AC18: 0 | AD18: 2 | AE18: =SUM(O18:AD18)/100 -> 0.75 | AF18: ='P3.1.1 (KPI ca nhan-Senior)'!M9 -> 0.35 | AG18: =100%-AF18 -> 0.65 | AH18: =AG18*0.6 -> 0.39 | AI18: ='P3.1.1 (KPI Phong Ban)'!M8 -> 0.9 | AJ18: =100%-AI18 -> 0.1 | AK18: =AJ18*0.4 -> 0.04 | AL18: =(AH18+AK18) -> 0.43 | AM18: =IF(AL18>=1,1,IF(AL18>=0.9,0.8,IF(AL18>=0.8,0.7,IF(AL18>=0.7,0.5,0)))) -> 0 | AN18: Dành cho kế toán
C20: III | D20: ĐÁNH GIÁ & Ý KIẾN CỦA TBP/ NGƯỜI ĐÁNH GIÁ
C21: STT | D21: Mã nhân viên | E21: Họ và tên | F21: Chức vụ | G21: Đánh giá và ý kiến trưởng bộ phận
C22: 1 | D22: E706 | E22: Nguyễn Hoàng Minh Nhựt | F22: Senior
