Workbook

Sheet LO TRINH CD
A1: LỘ TRÌNH CÔNG DANH - ADE 2026 - PHÒNG KẾ TOÁN
A2: Stt | B2: Kỹ năng/ Kiến thức/ Thái độ/ Kết quả/ Thời gian cống hiến | C2: Nhân viên | D2: Lộ trình | E2: Kế toán tổng hợp | F2: Lộ trình | G2: Kế toán trưởng | H2: Tài liệu Training (Link) | I2: Người đào tạo
A3: A | B3: KỸ NĂNG
A4: I | B4: Group 1. Kỹ năng cơ bản | D4: < 2 tháng (kể từ khi nhận việc)
A5: 1 | B5: Kỹ năng lập kế hoạch hàng ngày (Kế hoạch 5 phút) | C5: x | E5: x | F5: Passed | G5: x | H5: To do List (Excell)
A6: 2 | B6: Kỹ năng lập kế hoạch, báo cáo tuần/ tháng/ quí/ năm | C6: x | E6: x | F6: Passed | G6: x
A7: 3 | B7: Kỹ năng làm việc theo qui trình, không có qui trình thì thực hiện theo hướng dẫn của người quản lý trực tiếp | C7: x | E7: x | F7: Passed | G7: x | H7: Qui trình | I7: TBP
A8: 4 | B8: Kỹ năng sử dụng phần mềm vào công việc được giao | C8: x | E8: x | F8: Passed | G8: x | H8: Microsoft office, phần mềm báo cáo, kế toán | I8: Tự học/ TBP
A9: 5 | B9: Kỹ năng nhận dạng và giải quyết vấn đề (vấn đề và phương án) | C9: x | E9: x | F9: Passed | G9: x | H9: A Tân cung cấp | I9: TBP
A10: 6 | B10: Làm việc nhóm hoặc độc lập | C10: x | E10: x | F10: Passed | G10: x | H10: A Tân cung cấp | I10: TBP
A11: 7 | B11: Tiếng anh/ đọc hiểu và trả lời mail, tài liệu | C11: x | E11: x | F11: Passed | G11: x | H11: A Tân cung cấp | I11: Tự học
A12: 8 | B12: Quản lý thời gian | C12: x | E12: x | F12: Passed | G12: x | H12: A Tân cung cấp | I12: TBP
A13: 9 | B13: Kỹ năng nhập liệu, thống kê | C13: x | E13: x | F13: Passed | G13: x | I13: Tự học/ TBP
A14: II | B14: Group 2. Kỹ năng nâng cao
A15: 1 | B15: Kỹ năng giao tiếp, xây dựng mối quan hệ, kỹ năng thuyết trình, trình bày | C15: x | D15: < 3 tháng | E15: x | F15: Passed | G15: x | I15: TBP
A16: 2 | B16: Kỹ năng xây dựng qui trình | C16: x | D16: < 4 tháng | E16: x | F16: Passed | G16: x | H16: A Hưng cung cấp | I16: TBP
A17: 3 | B17: Xây dựng KPI, chính sách phúc lợi cho phòng | D17: < 5 tháng | E17: x | F17: Passed | G17: x | H17: HS, xây dựng LTCD và lương 3P | I17: TBP
A18: 4 | B18: Quản lý đội nhóm & tạo động lực cho nhân viên | D18: < 6 tháng | E18: x | F18: Passed | G18: x | H18: A Tân cung cấp | I18: TBP
A19: 5 | B19: Đào tạo nhân viên | D19: < 7 tháng | E19: x | F19: Passed | G19: x | H19: Qui trình đào tạo (theo Lộ trình đào tạo) | I19: TBP
A20: 6 | B20: Điều phối cuộc họp | D20: < 8 tháng | E20: x | F20: Passed | G20: x | H20: A Hưng cung cấp | I20: TBP
A21: 7 | B21: Tiếng anh/ đọc hiểu và trả lời mail, tài liệu, giao tiếp được | D21: < 12 tháng | E21: x | F21: Passed | G21: x | H21: A Tân cung cấp | I21: TBP
A22: III | B22: Group 3. Kỹ năng chuyên nghiệp
A23: 1 | B23: Quản trị hệ thống & qui trình | E23: x | F23: < 2 tháng | G23: x | H23: A Trọng cung cấp Index QT ISO (Update) | I23: TBP
A24: 2 | B24: Kỹ năng giao việc và huấn luyện | E24: x | F24: < 2 tháng | G24: x | H24: A Tân cung cấp | I24: TBP
A25: 3 | B25: Quản trị rủi ro | E25: x | F25: < 3 tháng | G25: x | H25: A Trọng cung cấp Index QT ISO (Update) | I25: TBP
A26: 4 | B26: Tiếng anh/ đọc hiểu và trả lời mail, tài liệu, giao tiếp được vs người nước ngoài | G26: x | H26: A Tân cung cấp | I26: TBP
A27: 5 | B27: Giám sát và điều hành | G27: x | H27: A Tân cung cấp | I27: TBP
A28: 6 | B28: Hoạch định chiến lược | G28: x | H28: A Tân cung cấp | I28: TBP
A29: 7 | B29: Phân tích và ra quyết định | G29: x | H29: A Tân cung cấp | I29: TBP
A30: 8 | B30: Quản trị sự thay đổi | G30: x | H30: A Tân cung cấp | I30: TBP
A31: B | B31: KIẾN THỨC
A32: I | B32: Kiến thức kế toán chung ( Các phương pháp, công thức)
A33: 1 | B33: Nguyên lý kế toán | C33: x | D33: Passed | E33: x | F33: Passed | G33: x | I33: Tự học
A34: 2 | B34: Soạn thảo văn bản (hợp đồng, công văn,…) | C34: x | E34: x | F34: Passed | G34: x | I34: Tự học/ TBP
A35: 3 | B35: Tạo lập, lưu trữ chứng từ kế toán (phiếu thu, chi, ủy nhiệm chi, lệnh chi,…) | C35: x | E35: x | F35: Passed | G35: x | I35: Tự học/ TBP
A36: 4 | B36: Kiểm tra, ghi chép, theo dõi sổ sách kế toán (hoàn toàn trên phần mềm) | C36: x | E36: x | F36: Passed | G36: x | I36: Tự học/ TBP
A37: 5 | B37: Cân đối kế hoạch thu chi hợp lý | C37: x | E37: x | F37: Passed | G37: x | I37: Tự học/ TBP
A38: 6 | B38: Tính lương theo quy định của công ty | C38: x | E38: x | F38: Passed | G38: x | I38: Tự học/ TBP
A39: 7 | B39: Lập các báo cáo nội bộ | C39: x | E39: x | F39: Passed | G39: x | I39: Tự học/ TBP
A40: 8 | B40: Quy định các loại thuế hiện hành | C40: x | E40: x | F40: Passed | G40: x | I40: Tự học/ TBP
...

Sheet P2.1 (Kien thuc)
A1: CÔNG TY TNHH KỸ THUẬT TỰ ĐỘNG AN DƯƠNG
A2: ĐÁNH GIÁ NHÂN VIÊN PHÒNG KẾ TOÁN
B3: Ngày: | C3: 30/04/2026 | E3: Người đánh giá:
B4: Mục đích kiểm tra/ đánh giá: | C4: Tháng 04/2026 | F4: Điểm đánh giá
A5: Stt | B5: Kỹ năng/ Kiến thức/ Thái độ/ Kết quả/ Thời gian làm việc | C5: Thang điểm Cộng/ trừ (Tham khảo) | D5: Thang điểm 100 | E5: Diễn giải | F5: Nguyễn Ngọc Diệp
A6: A | B6: KỸ NĂNG | D6: =D7+D17+D25 -> 40 | E6: KỸ NĂNG | F6: =F7+F17+F25 -> 37
A7: I | B7: Group 1. Kỹ năng cơ bản | D7: 20 | E7: Group 1. Kỹ năng cơ bản | F7: =$D$7+SUM(F8:F16) -> 19
A8: 1 | B8: Không có kế hoạch hàng ngày (Kế hoạch 5 phút) | C8: -1 | E8: Kỹ năng lập kế hoạch hàng ngày (Kế hoạch 5 phút)
A9: 2 | B9: Không có kế hoạch, báo cáo tuần/ tháng/ quí/ năm | C9: -2 | E9: Kỹ năng lập kế hoạch, báo cáo tuần/ tháng/ quí/ năm
A10: 3 | B10: Không làm việc theo qui trình, không thực hiện theo hướng dẫn của người quản lý trực tiếp | C10: -2 | E10: Kỹ năng làm việc theo qui trình, không có qui trình thì thực hiện theo hướng dẫn của người quản lý trực tiếp
A11: 4 | B11: Không sử dụng phần mềm vào công việc được giao | C11: -1 | E11: Kỹ năng sử dụng phần mềm vào công việc được giao
A12: 5 | B12: Không hợp tác làm việc nhóm | C12: -2 | E12: Làm việc nhóm hoặc độc lập
A13: 6 | B13: Không chủ động nhận dạng và giải quyết vấn đề | C13: -2 | E13: Kỹ năng nhận dạng và giải quyết vấn đề (vấn đề và phương án)
A14: 7 | B14: Không đọc được tiếng anh/ đọc hiểu bản vẽ, tài liệu tiếng anh | C14: -1 | E14: Tiếng anh/ đọc hiểu và trả lời mail, tài liệu | F14: -1
A15: 8 | B15: Không biết Quản lý thời gian & sắp xếp công việc phù hợp | C15: -2 | E15: Quản lý thời gian
A16: 9 | B16: Không hạch toán đúng các nghiệp vụ phát sinh | C16: -2 | E16: Kỹ năng nhập liệu, thống kê
A17: II | B17: Group 2. Kỹ năng nâng cao | D17: 10 | E17: Group 2. Kỹ năng nâng cao | F17: =$D$17+SUM(F18:F24) -> 8
A18: 1 | B18: Kỹ năng giao tiếp, xây dựng mối quan hệ, kỹ năng thuyết trình, trình bày | C18: -2 | E18: Kỹ năng giao tiếp, xây dựng mối quan hệ, kỹ năng thuyết trình, trình bày
A19: 2 | B19: Không biết viết qui trình/ hướng dẫn | C19: -2 | E19: Kỹ năng xây dựng qui trình
A20: 3 | B20: Không xây dựng KPI, chính sách phúc lợi cho phòng | C20: -1 | E20: Xây dựng KPI, chính sách phúc lợi cho phòng
A21: 4 | B21: Không quản lý đội nhóm & tạo động lực cho nhân viên | C21: -1 | E21: Quản lý đội nhóm & tạo động lực cho nhân viên
A22: 5 | B22: Không kỹ năng đào tạo nhân viên | C22: -1 | E22: Đào tạo nhân viên
A23: 6 | B23: Không điều phối tốt cuộc họp | C23: -1 | E23: Điều phối cuộc họp | F23: -1
A24: 7 | B24: Không có kiến thức về tiếng anh/ đọc hiểu và trả lời mail, tài liệu, giao tiếp được | C24: -1 | E24: Tiếng anh/ đọc hiểu và trả lời mail, tài liệu, giao tiếp được | F24: -1
A25: III | B25: Group 3. Kỹ năng chuyên nghiệp | D25: 10 | E25: Group 3. Kỹ năng chuyên nghiệp | F25: =$D$25+SUM(F26:F33) -> 10
A26: 1 | B26: Quản trị hệ thống & qui trình | C26: -1 | E26: Quản trị hệ thống & qui trình
A27: 2 | B27: Kỹ năng giao việc và huấn luyện | C27: -1 | E27: Kỹ năng giao việc và huấn luyện
A28: 3 | B28: Quản trị rủi ro | C28: -1 | E28: Quản trị rủi ro
A29: 4 | B29: Tiếng anh/ đọc hiểu và trả lời mail, tài liệu, giao tiếp được vs người nước ngoài | C29: -2 | E29: Tiếng anh/ đọc hiểu và trả lời mail, tài liệu, giao tiếp được vs người nước ngoài
A30: 5 | B30: Giám sát và điều hành | C30: -1 | E30: Giám sát và điều hành
A31: 6 | B31: Kỹ năng giao việc và huấn luyện | C31: -1 | E31: Hoạch định chiến lược
A32: 7 | B32: Phân tích và ra quyết định | C32: -1 | E32: Phân tích và ra quyết định
A33: 8 | B33: Quản trị sự thay đổi | C33: -1 | E33: Quản trị sự thay đổi
A34: B | B34: KIẾN THỨC | D34: =D35+D57+D74 -> 35 | E34: KIẾN THỨC | F34: =F35+F57+F74 -> 35
A35: I | B35: Kiến thức nền (Các công thức, phương pháp) | D35: 20 | E35: Kiến thức kế toán chung ( Các phương pháp, công thức) | F35: =$D$35+SUM(F36:F56) -> 20
A36: 1 | B36: Nguyên lý kế toán | C36: -5 | E36: Nguyên lý kế toán
A37: 2 | B37: Soạn thảo văn bản (hợp đồng, công văn,…) | C37: -5 | E37: Soạn thảo văn bản (hợp đồng, công văn,…)
A38: 3 | B38: Tạo lập, lưu trữ chứng từ kế toán (phiếu thu, chi, ủy nhiệm chi, lệnh chi,…) | C38: -5 | E38: Tạo lập, lưu trữ chứng từ kế toán (phiếu thu, chi, ủy nhiệm chi, lệnh chi,…)
A39: 4 | B39: Kiểm tra, ghi chép, theo dõi sổ sách kế toán (hoàn toàn trên phần mềm) | C39: -5 | E39: Kiểm tra, ghi chép, theo dõi sổ sách kế toán (hoàn toàn trên phần mềm)
A40: 5 | B40: Cân đối kế hoạch thu chi hợp lý | C40: -5 | E40: Cân đối kế hoạch thu chi hợp lý
...

Sheet P2.2 (Ky nang chuyen mon)
D2: BẢNG TỔNG HỢP ĐÁNH GIÁ THỰC HIỆN CÔNG VIỆC NHÂN VIÊN VĂN PHÒNG | S2: Mã số
S3: Lần ban hành
S4: Lần sửa đổi
H6: PHÒNG: | I6: Kế toán
H7: Tháng: 04/2026
B9: STT | C9: HỌ VÀ TÊN | D9: CHỨC VỤ | E9: CHỈ TIÊU ĐÁNH GIÁ | T9: TỔNG ĐIỂM | U9: XẾP LOẠI | V9: GHI CHÚ
E10: 1 | F10: 2 | G10: 3 | H10: 4 | I10: 5 | J10: 6 | K10: 7 | L10: 8 | M10: 9 | N10: 10 | O10: 11 | P10: 12 | Q10: 13 | R10: 14 | S10: 15
E11: Kiến thức & kỹ năng thực hiện công việc | F11: Khối lượng & chất lượng thực hiện công việc | G11: Tinh thần hợp tác, khả năng làm việc nhóm & hiệu quả công việc chung | H11: Tự chủ & linh hoạt trong giải quyết công việc | I11: Khả năng tổng hợp, phân loại & xử lý thông tin | J11: Khả năng sáng tạo, cải tiến & tự phát triển | K11: Thái độ, ý thức trách nhiệm đối với công việc | L11: Mối quan hệ với khách hàng và đối tác | M11: Ý thức kỷ luật, tuân thủ nội quy; ý thức chấp hành lệnh phân công, điều hành của quản trị viên, BGĐ | N11: Mặc đồng phục & đeo biển tên | O11: Ý thức sử dụng thời gian làm việc | P11: Ý thức sử dụng tài sảm của công ty (VPP điện, nước, thiết bị văn phòng, máy tính…) | Q11: Giữ gìn vệ sinh & môi trường làm việc tại cơ quan | R11: Đi làm đầy đủ | S11: Đi làm đúng giờ
E12: 9 | F12: 9 | G12: 9 | H12: 9 | I12: 9 | J12: 6 | K12: 6 | L12: 6 | M12: 6 | N12: 6 | O12: 5 | P12: 5 | Q12: 5 | R12: 5 | S12: 5 | T12: 100
B13: 1 | C13: Nguyễn Ngọc Diệp | D13: NV | E13: 8 | F13: 7 | G13: 8 | H13: 8 | I13: 8 | J13: 5 | K13: 5 | L13: 5 | M13: 5 | N13: 5 | O13: 5 | P13: 5 | Q13: 5 | R13: 4 | S13: 5 | T13: =SUM(E13:S13) -> 88
C14: TBP đánh giá (nếu có) | T14: =SUM(E14:S14) -> 0
C15: QTV đánh giá | T15: =SUM(E15:S15) -> 0
B16: 3 | D16: CN
C17: TBP đánh giá (nếu có)
C18: QTV đánh giá
P20: TP. HCM, ngày 30 tháng 04 năm 2026
D21: TRƯỞNG PHÒNG | Q21: TỔNG GIÁM ĐỐC

Sheet P3.1.1 (KPI ca nhan)
C1: QUẢN TRỊ HIỆU SUẤT | D1: CÔNG TY TNHH KỸ THUẬT TỰ ĐỘNG AN DƯƠNG BẢNG KPI CÁ NHÂN PHÒNG KẾ TOÁN THÁNG 04/2026 | L1: Mã số: ADE-2024-KPI P.KTOAN Phiên bản: RV01 Hiệu lực: 01/2024 | M1: NHẬN XÉT CỦA QUẢN TRỊ HIỆU SUẤT
C3: Căn cứ quy định đánh giá hiệu quả công việc hiện hành
C4: Căn cứ kế hoạch phát triển công ty
A5: PHÒNG KẾ TOÁN | B5: Mục tiêu chiến lược | C5: Yếu tố quyết định thành công | D5: Chỉ tiêu đánh giá (KPI) | E5: Stt KPI | F5: Đơn vị đo lường | G5: Trọng số (%) | H5: Thực hiện cùng kỳ 2024 | I5: Mục tiêu 2025 | J5: Kém | K5: Xuất sắc | L5: Đơn vị chịu trách nhiệm | Q5: Điểm Đánh Giá
Q6: Nguyễn Ngọc Diệp
M7: Phân loại KPI ? | N7: Tính kiểm soát ? | O7: Mức độ tương thích giữa các chỉ số đạt được với mục tiêu chiến lược | P7: Các nội dung khác | Q7: Số lần vi phạm | R7: Điểm thưởng bị trừ
A8: Tổng cộng | G8: =SUM(G9:G18) -> 1 | Q8: =SUM(Q9:Q18) -> 0 | R8: =SUM(R9:R18) -> 0
A9: Tài chính kế toán | B9: Kế hoạch thu chi hợp lý | C9: Nắm được thông tin từ các nguồn tin đáng tin cậy | D9: Chọn lọc thông tin đáng tin cậy để lên kế hoạch hợp lý | E9: KPI 1.KTOAN | F9: Số lần vi phạm/tháng (1 tuần/lần) | G9: 0.1 | I9: 1 lần / tháng | J9: 2 lần / tháng | K9: 0 lần/ tháng | L9: Phòng kế toán | M9: KPI | N9: Đo lường hàng tháng | O9: Tương đối
B10: Báo cáo đúng hạn | C10: Số liệu được hạch toán đầy đủ, chính xác | D10: Nhập liệu sai dẫn đến trể tiến độ báo cáo | F10: Số lần vi phạm/báo cáo | G10: 0.1 | I10: 5 lần/báo cáo lớn (tài chính, thuế) 2 lần/ báo cáo nội bộ | J10: 6 lần/báo cáo lớn (tài chính, thuế) 3 lần/ báo cáo nội bộ | K10: 3 lần/báo cáo lớn (tài chính, thuế) 0 lần/ báo cáo nội bộ | L10: Phòng kế toán | M10: KPI | N10: Đo lường hàng tháng | O10: Tương đối
B11: Tính lương đúng đủ | C11: Các bộ phận gửi đúng ngày theo quy định | D11: Tính thiếu, tính dư lương NV công ty | F11: Số lần vi phạm/ tháng | G11: 0.1 | I11: 0 lần/tháng | J11: 1 lần/tháng | K11: 0 lần/tháng | L11: Phòng kế toán | M11: KPI | N11: Đo lường hàng tháng | O11: Tương đối
B12: Quản lý tốt & chặt chẽ tài chính của Cty. | C12: Báo cáo đầy đủ, kịp thời, rõ ràng, dễ hiểu, chính xác & trung thực số liệu kế toán. | D12: Báo cáo không phù hợp, không trung thực với số liệu thực tế | F12: Số lần vi phạm/báo cáo | G12: 0.1 | I12: 1 lần/báo cáo | J12: 2 lần/báo cáo | K12: 0 lần/báo cáo | L12: Phòng kế toán | M12: KPI | N12: Đo lường hàng tháng | O12: Tương đối
B13: Sử dụng vốn hiệu quả | C13: Giảm chi phí: - Cắt giảm chi phí quảng cáo, in ấn, hoạt động Cty không cần thiết. - Giảm chi phí lãi vay (thu hồi công nợ đúng hạn, giảm bớt tiền vay). | D13: % Tổng chi phí thực tế/Tổng chi phí kế hoạch | F13: % | G13: 0.1 | I13: 0.8 | J13: 0.6 | K13: 0.9 | L13: Phòng kế toán | M13: KPI | N13: Đo lường hàng tháng | O13: Tương đối
A14: Quy trình P. Kế toán | B14: Quy trình và quản lý chất lượng | C14: Quy trình và quản lý việc thực hiện theo quy trình | D14: Áp dụng quy trình vào từng vị trí công việc | E14: KPI 2.KTOAN | F14: Số lần không áp dụng quy trình/ tháng | G14: 0.1 | I14: 3 lần/tháng | J14: 4 lần/tháng | K14: 1 lần/tháng | L14: Phòng kế toán | M14: KPI | N14: Đo lường hàng tháng | O14: Tương đối
C15: Hiệu suất | D15: Không cải tiến phương án thực hiện công việc làm ảnh hưởng chất lượng công việc | F15: Số lần /tháng | G15: 0.1 | I15: 5 lần/tháng | J15: 6 lần/tháng | K15: 2 lần/tháng | L15: Phòng kế toán | M15: KPI | N15: Đo lường hàng tháng
D16: Qui trình 5S | F16: Số lần vi phạm/ không thực hiện/tháng | G16: 0.1 | I16: 1 lần/tháng | J16: 2 lần/tháng | K16: 0 lần/tháng | L16: Phòng kế toán | M16: KPI | N16: Đo lường hàng tháng | O16: Tương đối
A17: Đào tạo và phẩm chất | B17: Chất lượng nhân sự | C17: Chất lượng nhân sự đáp ứng nhu cầu | D17: Năng lực làm việc | E17: KPI 3.KTOAN | F17: % | G17: 0.1 | I17: 0.9 | J17: 0.7 | K17: 1 | L17: Phòng kế toán | M17: KPI | N17: Đo lường hàng tháng | O17: Tương đối
B18: Tuân thủ quy định công ty | C18: Tuân thủ nội quy, quy định công ty | D18: Không thực hiện nội quy, quy định công ty | F18: Số lần vi phạm/ tháng | G18: 0.1 | I18: 2 lần/tháng | J18: 3 lần/tháng | K18: 0 lần/tháng | L18: Phòng kế toán | M18: KPI | N18: Đo lường hàng tháng | O18: Tương đối

Sheet P3.1.2 (KPI PKTOAN)
C1: QUẢN TRỊ HIỆU SUẤT | D1: CÔNG TY TNHH KỸ THUẬT TỰ ĐỘNG AN DƯƠNG BẢNG KPI PHÒNG KẾ TOÁN THÁNG 04/2026 | L1: Mã số: ADE-2024-KPI P.KTOAN Phiên bản: RV01 Hiệu lực: 01/2024 | M1: NHẬN XÉT CỦA QUẢN TRỊ HIỆU SUẤT
C3: Căn cứ quy định đánh giá hiệu quả công việc hiện hành
C4: Căn cứ kế hoạch phát triển công ty
A6: PHÒNG KẾ TOÁN | B6: Mục tiêu chiến lược | C6: Yếu tố quyết định thành công | D6: Chỉ tiêu đánh giá (KPI) | E6: Stt KPI | F6: Đơn vị đo lường | G6: Trọng số (%) | H6: Thực hiện cùng kỳ 2025 | I6: Mục tiêu 2026 | J6: Kém | K6: Xuất sắc | L6: Đơn vị chịu trách nhiệm | Q6: Điểm Đánh Giá
M7: Phân loại KPI ? | N7: Tính kiểm soát ? | O7: Mức độ tương thích giữa các chỉ số đạt được với mục tiêu chiến lược | P7: Các nội dung khác | Q7: Số lần vi phạm | R7: Điểm thưởng bị trừ
A8: Tổng cộng | G8: =SUM(G9:G18) -> 1 | Q8: =SUM(Q9:Q18) -> 0 | R8: =SUM(R9:R18) -> 0
A9: Tài chính kế toán | B9: Kế hoạch thu chi hợp lý | C9: Nắm được thông tin từ các nguồn tin đáng tin cậy | D9: Chọn lọc thông tin đáng tin cậy để lên kế hoạch hợp lý | E9: KPI 1.KTOAN | F9: Số lần vi phạm/tháng (1 tuần/lần) | G9: 0.1 | I9: 1 lần / tháng | J9: 2 lần / tháng | K9: 0 lần/ tháng | L9: Phòng kế toán | M9: KPI | N9: Đo lường hàng tháng | O9: Tương đối
B10: Báo cáo đúng hạn | C10: Số liệu được hạch toán đầy đủ, chính xác | D10: Nhập liệu sai dẫn đến trể tiến độ báo cáo | F10: Số lần vi phạm/báo cáo | G10: 0.1 | I10: 5 lần/báo cáo lớn (tài chính, thuế) 2 lần/ báo cáo nội bộ | J10: 6 lần/báo cáo lớn (tài chính, thuế) 3 lần/ báo cáo nội bộ | K10: 3 lần/báo cáo lớn (tài chính, thuế) 0 lần/ báo cáo nội bộ | L10: Phòng kế toán | M10: KPI | N10: Đo lường hàng tháng | O10: Tương đối
B11: Tính lương đúng đủ | C11: Các bộ phận gửi đúng ngày theo quy định | D11: Tính thiếu, tính dư lương NV công ty | F11: Số lần vi phạm/ tháng | G11: 0.1 | I11: 0 lần/tháng | J11: 1 lần/tháng | K11: 0 lần/tháng | L11: Phòng kế toán | M11: KPI | N11: Đo lường hàng tháng | O11: Tương đối
B12: Quản lý tốt & chặt chẽ tài chính của Cty. | C12: Báo cáo đầy đủ, kịp thời, rõ ràng, dễ hiểu, chính xác & trung thực số liệu kế toán. | D12: Báo cáo không phù hợp, không trung thực với số liệu thực tế | F12: Số lần vi phạm/báo cáo | G12: 0.1 | I12: 1 lần/báo cáo | J12: 2 lần/báo cáo | K12: 0 lần/báo cáo | L12: Phòng kế toán | M12: KPI | N12: Đo lường hàng tháng | O12: Tương đối
B13: Sử dụng vốn hiệu quả | C13: Giảm chi phí: - Cắt giảm chi phí quảng cáo, in ấn, hoạt động Cty không cần thiết. - Giảm chi phí lãi vay (thu hồi công nợ đúng hạn, giảm bớt tiền vay). | D13: % Tổng chi phí thực tế/Tổng chi phí kế hoạch | F13: % | G13: 0.1 | I13: 0.8 | J13: 0.6 | K13: 0.9 | L13: Phòng kế toán | M13: KPI | N13: Đo lường hàng tháng | O13: Tương đối
A14: Quy trình P. Kế toán | B14: Quy trình và quản lý chất lượng | C14: Quy trình và quản lý việc thực hiện theo quy trình | D14: Áp dụng quy trình vào từng vị trí công việc | E14: KPI 2.KTOAN | F14: Số lần không áp dụng quy trình/ tháng | G14: 0.1 | I14: 3 lần/tháng | J14: 4 lần/tháng | K14: 1 lần/tháng | L14: Phòng kế toán | M14: KPI | N14: Đo lường hàng tháng | O14: Tương đối
C15: Hiệu suất | D15: Không cải tiến phương án thực hiện công việc làm ảnh hưởng chất lượng công việc | F15: Số lần /tháng | G15: 0.1 | I15: 5 lần/tháng | J15: 6 lần/tháng | K15: 2 lần/tháng | L15: Phòng kế toán | M15: KPI | N15: Đo lường hàng tháng
D16: Qui trình 5S | F16: Số lần vi phạm/ không thực hiện/tháng | G16: 0.1 | I16: 1 lần/tháng | J16: 2 lần/tháng | K16: 0 lần/tháng | L16: Phòng kế toán | M16: KPI | N16: Đo lường hàng tháng | O16: Tương đối
A17: Đào tạo và phẩm chất | B17: Chất lượng nhân sự | C17: Chất lượng nhân sự đáp ứng nhu cầu | D17: Năng lực làm việc | E17: KPI 3.KTOAN | F17: % | G17: 0.1 | I17: 0.9 | J17: 0.7 | K17: 1 | L17: Phòng kế toán | M17: KPI | N17: Đo lường hàng tháng | O17: Tương đối
B18: Tuân thủ quy định công ty | C18: Tuân thủ nội quy, quy định công ty | D18: Không thực hiện nội quy, quy định công ty | F18: Số lần vi phạm/ tháng | G18: 0.1 | I18: 2 lần/tháng | J18: 3 lần/tháng | K18: 0 lần/tháng | L18: Phòng kế toán | M18: KPI | N18: Đo lường hàng tháng | O18: Tương đối

Sheet KET QUA DANH GIA 3P - T04.26
D2: BẢNG ĐÁNH GIÁ THEO PHƯƠNG PHÁP 3P THÁNG 04/2026 | AO2: No.KTOAN Date: 30/04/2026 Page: 01/01
C6: I | D6: THÔNG TIN CHUNG
D7: Bộ phận được đánh giá: | E7: Kế toán
D8: Người đánh giá:
D9: Tiêu chí đánh giá | E9: Phương pháp 3P với trọng số
D12: Chú ý: đây là bảng tổng hợp Lương 3P của nhân viên phòng ban. Cuối mỗi tháng, trưởng bộ phận sẽ đánh giá nhân viên các tiêu chí P2.1; P2.2; P3.1.1; P3.1.2 tại các sheet tương ứng
C13: II | D13: BẢNG TỔNG HỢP KẾT QUẢ
C14: STT | D14: Mã nhân viên | E14: Họ và tên | F14: Chức vụ | G14: TIÊU CHÍ P1 (lương theo vị trí) | I14: TIÊU CHÍ P2 (lương theo năng lực) | AE14: TIÊU CHÍ P3 (lương theo hiệu quả công việc)
G15: P1.1 (lương cơ bản) | H15: P1.2 (lương chuyên môn, chức vụ) Đánh giá theo định kỳ | I15: P2.1 (lương theo kiến thức công việc) Đánh giá theo định kỳ | O15: P2.2 (lương theo kỹ năng, kinh nghiệm) Đánh giá theo định kỳ | AE15: P3.1 | AM15: P3.2 (theo doanh thu)
AE16: P3.1.1 KPI CÁ NHÂN (1) | AH16: P3.1.2 KPI PHÒNG BAN (2) | AL16: KPI NHÂN VIÊN= (1) X (2) | AN16: Tổng | AO16: Ghi chú
G17: Mức lương | H17: Mức lương | I17: TC1 | J17: TC2 | K17: TC3 | L17: TC4 | M17: TC5 | N17: Hệ số | O17: TC1 | P17: TC2 | Q17: TC3 | R17: TC4 | S17: TC5 | T17: TC6 | U17: TC7 | V17: TC8 | W17: TC9 | X17: TC10 | Y17: TC11 | Z17: TC12 | AA17: TC13 | AB17: TC14 | AC17: TC15 | AD17: Hệ số | AE17: Điểm thưởng bị trừ | AF17: Điểm | AG17: Trọng số: 0.6 | AH17: Điểm thưởng bị trừ | AI17: Điểm | AJ17: Trọng số: 0.4 | AK17: Tổng trọng số | AL17: Hệ số | AM17: Hệ số
C18: 1 | D18: E203 | E18: Nguyễn Ngọc Diệp | F18: Kế toán | G18: dành cho kế toán | H18: dành cho kế toán | I18: ='P2.1 (Kien thuc)'!F6 -> 37 | J18: ='P2.1 (Kien thuc)'!F34 -> 35 | K18: ='P2.1 (Kien thuc)'!F88 -> 15 | L18: ='P2.1 (Kien thuc)'!F96 -> 5 | M18: ='P2.1 (Kien thuc)'!F102 -> 5 | N18: =SUM(I18:M18)/100 -> 0.97 | O18: ='P2.2 (Ky nang chuyen mon)'!E13 -> 8 | P18: ='P2.2 (Ky nang chuyen mon)'!F13 -> 7 | Q18: ='P2.2 (Ky nang chuyen mon)'!G13 -> 8 | R18: ='P2.2 (Ky nang chuyen mon)'!H13 -> 8 | S18: ='P2.2 (Ky nang chuyen mon)'!I13 -> 8 | T18: ='P2.2 (Ky nang chuyen mon)'!J13 -> 5 | U18: ='P2.2 (Ky nang chuyen mon)'!K13 -> 5 | V18: ='P2.2 (Ky nang chuyen mon)'!L13 -> 5 | ... AC18: ='P2.2 (Ky nang chuyen mon)'!S13 -> 5 | AD18: =SUM(O18:AC18)/100 -> 0.88 | AE18: ='P3.1.1 (KPI ca nhan)'!R8 -> 0 | AF18: =100%-AE18 -> 1 | AG18: =AF18*0.6 -> 0.6 | AH18: ='P3.1.2 (KPI PKTOAN)'!R8 -> 0 | AI18: =100%-AH18 -> 1 | AJ18: =AI18*0.4 -> 0.4 | AK18: =AG18+AJ18 -> 1 | AL18: =IF(AK18>=1,1,IF(AK18>=0.9,0.8,IF(AK18>=0.8,0.7,IF(AK18>=0.7,0.5,0)))) -> 1 | AM18: dành cho kế toán
C20: III | D20: ĐÁNH GIÁ & Ý KIẾN CỦA TBP
C21: STT | D21: Mã nhân viên | E21: Họ và tên | F21: Chức vụ | G21: Đánh giá và ý kiến trưởng bộ phận
C22: 1 | D22: E203 | E22: Nguyễn Ngọc Diệp | F22: Kế toán
